Workbook

Sheet הוראות
A1: תבנית איסוף נתונים – מסלול יצירת גישה לדיאליזה (AV Fistula)
A3: איך ממלאים:
A4: 1. בגיליון 'נתונים' ממלאים רק את התאים הצהובים. התאים הירוקים מחושבים אוטומטית.
A5: 2. אין לרשום שם, ת.ז. או מספר תיק – רק מספר סידורי.
A6: 3. תאריכים בפורמט dd/mm/yyyy. אם שלב לא בוצע או לא ידוע – משאירים ריק.
A7: 4. סוג גישה, איך התחילה דיאליזה וסיבת עיכוב – בוחרים מהרשימה הנפתחת.
A8: 5. גיליון 'סיכום' מתעדכן לבד: חציון, ממוצע, מינימום ומקסימום לכל שלב, ופילוח סיבות עיכוב.
A9: 6. חציון הוא המדד העיקרי – הוא פחות מושפע ממקרים קיצוניים.
A11: שורת דוגמה (לא נכללת בחישובים):
A12: מס' סידורי | B12: גיל | C12: תאריך הפניה | D12: תאריך מיפוי דופלקס | E12: תאריך ביקור במרפאה | F12: תאריך ניתוח | G12: סוג גישה | H12: התחלת דיאליזה | I12: סיבת עיכוב עיקרית
A13: 1 | B13: 67 | C13: 45964 | D13: 45992 | E13: 46013 | F13: 46062 | G13: AVF | H13: פיסטולה | I13: המתנה למיפוי
A15: מקור קודי הפעולה: ICD-9-CM 39.27 (Arteriovenostomy for renal dialysis) – לאמת מול מחלקת הקידוד בבית החולים.
A17: הערה: הגיליון מולא בנתוני הדגמה מדומים (סימולציה, 84 שורות) לצורך בדיקת התבנית, הנוסחאות וגיליון הסיכום. לפני השימוש בעבודה יש להחליפם בנתוני הרשומות בפועל, לאחר אישור מנהל המחלקה ואימות מול מחלקת הקידוד.
A18: תקופת ההדגמה: ניתוחים שבוצעו בין 01/06/2025 ל-31/05/2026. שורות עם תאריך מיפוי או מרפאה חסר נשארו ריקות בהתאם להוראה 3.

Sheet נתונים
A1: מס' סידורי | B1: גיל | C1: תאריך הפניה | D1: תאריך מיפוי דופלקס | E1: תאריך ביקור במרפאה | F1: תאריך ניתוח | G1: סוג גישה | H1: התחלת דיאליזה | I1: סיבת עיכוב עיקרית | J1: הערות | K1: ימים: הפניה → מיפוי | L1: ימים: מיפוי → מרפאה | M1: ימים: מרפאה → ניתוח | N1: ימים: הפניה → ניתוח (סה"כ)
A2: 1 | B2: 37 | C2: 45647 | E2: 45734 | F2: 45809 | G2: AVF | H2: צנתר | I2: אחר | J2: מיפוי בוצע בקהילה, תאריך לא ידוע | K2: =IF(AND(ISNUMBER(C2),ISNUMBER(D2)),D2-C2,"") | L2: =IF(AND(ISNUMBER(D2),ISNUMBER(E2)),E2-D2,"") | M2: =IF(AND(ISNUMBER(E2),ISNUMBER(F2)),F2-E2,"") -> 75 | N2: =IF(AND(ISNUMBER(C2),ISNUMBER(F2)),F2-C2,"") -> 162
A3: 2 | B3: 68 | C3: 45749 | D3: 45775 | E3: 45790 | F3: 45813 | G3: AVF | H3: צנתר | I3: הפניה מאוחרת מנפרולוגיה | K3: =IF(AND(ISNUMBER(C3),ISNUMBER(D3)),D3-C3,"") -> 26 | L3: =IF(AND(ISNUMBER(D3),ISNUMBER(E3)),E3-D3,"") -> 15 | M3: =IF(AND(ISNUMBER(E3),ISNUMBER(F3)),F3-E3,"") -> 23 | N3: =IF(AND(ISNUMBER(C3),ISNUMBER(F3)),F3-C3,"") -> 64
A4: 3 | B4: 61 | C4: 45646 | D4: 45694 | E4: 45747 | F4: 45815 | G4: AVG (שתל) | H4: טרם התחיל | I4: המתנה לתור במרפאה | K4: =IF(AND(ISNUMBER(C4),ISNUMBER(D4)),D4-C4,"") -> 48 | L4: =IF(AND(ISNUMBER(D4),ISNUMBER(E4)),E4-D4,"") -> 53 | M4: =IF(AND(ISNUMBER(E4),ISNUMBER(F4)),F4-E4,"") -> 68 | N4: =IF(AND(ISNUMBER(C4),ISNUMBER(F4)),F4-C4,"") -> 169
A5: 4 | B5: 73 | C5: 45733 | D5: 45753 | E5: 45766 | F5: 45821 | G5: AVF | H5: טרם התחיל | I5: ביטול ניתוח | J5: ניתוח בוטל ביום הניתוח ונקבע מחדש | K5: =IF(AND(ISNUMBER(C5),ISNUMBER(D5)),D5-C5,"") -> 20 | L5: =IF(AND(ISNUMBER(D5),ISNUMBER(E5)),E5-D5,"") -> 13 | M5: =IF(AND(ISNUMBER(E5),ISNUMBER(F5)),F5-E5,"") -> 55 | N5: =IF(AND(ISNUMBER(C5),ISNUMBER(F5)),F5-C5,"") -> 88
A6: 5 | B6: 49 | C6: 45672 | D6: 45690 | E6: 45712 | F6: 45834 | G6: AVF | H6: פיסטולה | I6: המתנה לחדר ניתוח | K6: =IF(AND(ISNUMBER(C6),ISNUMBER(D6)),D6-C6,"") -> 18 | L6: =IF(AND(ISNUMBER(D6),ISNUMBER(E6)),E6-D6,"") -> 22 | M6: =IF(AND(ISNUMBER(E6),ISNUMBER(F6)),F6-E6,"") -> 122 | N6: =IF(AND(ISNUMBER(C6),ISNUMBER(F6)),F6-C6,"") -> 162
A7: 6 | B7: 60 | C7: 45721 | E7: 45789 | F7: 45837 | G7: AVF | H7: פיסטולה | I7: אחר | J7: מיפוי בוצע בקהילה, תאריך לא ידוע | K7: =IF(AND(ISNUMBER(C7),ISNUMBER(D7)),D7-C7,"") | L7: =IF(AND(ISNUMBER(D7),ISNUMBER(E7)),E7-D7,"") | M7: =IF(AND(ISNUMBER(E7),ISNUMBER(F7)),F7-E7,"") -> 48 | N7: =IF(AND(ISNUMBER(C7),ISNUMBER(F7)),F7-C7,"") -> 116
A8: 7 | B8: 44 | C8: 45721 | E8: 45763 | F8: 45848 | G8: AVF | H8: צנתר | I8: המתנה לחדר ניתוח | J8: מיפוי בוצע בקהילה, תאריך לא ידוע | K8: =IF(AND(ISNUMBER(C8),ISNUMBER(D8)),D8-C8,"") | L8: =IF(AND(ISNUMBER(D8),ISNUMBER(E8)),E8-D8,"") | M8: =IF(AND(ISNUMBER(E8),ISNUMBER(F8)),F8-E8,"") -> 85 | N8: =IF(AND(ISNUMBER(C8),ISNUMBER(F8)),F8-C8,"") -> 127
A9: 8 | B9: 75 | C9: 45733 | D9: 45773 | E9: 45794 | F9: 45851 | G9: AVG (שתל) | H9: צנתר | I9: המתנה למיפוי | K9: =IF(AND(ISNUMBER(C9),ISNUMBER(D9)),D9-C9,"") -> 40 | L9: =IF(AND(ISNUMBER(D9),ISNUMBER(E9)),E9-D9,"") -> 21 | M9: =IF(AND(ISNUMBER(E9),ISNUMBER(F9)),F9-E9,"") -> 57 | N9: =IF(AND(ISNUMBER(C9),ISNUMBER(F9)),F9-C9,"") -> 118
A10: 9 | B10: 61 | C10: 45789 | D10: 45813 | E10: 45820 | F10: 45852 | G10: AVF | H10: פיסטולה | I10: ללא עיכוב משמעותי | K10: =IF(AND(ISNUMBER(C10),ISNUMBER(D10)),D10-C10,"") -> 24 | L10: =IF(AND(ISNUMBER(D10),ISNUMBER(E10)),E10-D10,"") -> 7 | M10: =IF(AND(ISNUMBER(E10),ISNUMBER(F10)),F10-E10,"") -> 32 | N10: =IF(AND(ISNUMBER(C10),ISNUMBER(F10)),F10-C10,"") -> 63
A11: 10 | B11: 37 | C11: 45731 | D11: 45754 | E11: 45792 | F11: 45854 | G11: AVF | H11: טרם התחיל | I11: המתנה לתור במרפאה | K11: =IF(AND(ISNUMBER(C11),ISNUMBER(D11)),D11-C11,"") -> 23 | L11: =IF(AND(ISNUMBER(D11),ISNUMBER(E11)),E11-D11,"") -> 38 | M11: =IF(AND(ISNUMBER(E11),ISNUMBER(F11)),F11-E11,"") -> 62 | N11: =IF(AND(ISNUMBER(C11),ISNUMBER(F11)),F11-C11,"") -> 123
A12: 11 | B12: 68 | C12: 45724 | D12: 45799 | E12: 45814 | F12: 45859 | G12: AVF | H12: טרם התחיל | I12: המתנה למיפוי | J12: לא הגיע לתור הראשון למיפוי (זימון לא התקבל) | K12: =IF(AND(ISNUMBER(C12),ISNUMBER(D12)),D12-C12,"") -> 75 | L12: =IF(AND(ISNUMBER(D12),ISNUMBER(E12)),E12-D12,"") -> 15 | M12: =IF(AND(ISNUMBER(E12),ISNUMBER(F12)),F12-E12,"") -> 45 | N12: =IF(AND(ISNUMBER(C12),ISNUMBER(F12)),F12-C12,"") -> 135
A13: 12 | B13: 69 | C13: 45743 | D13: 45810 | F13: 45861 | G13: AVF | H13: טרם התחיל | I13: המתנה למיפוי | J13: לא הגיע לתור הראשון למיפוי (זימון לא התקבל) | K13: =IF(AND(ISNUMBER(C13),ISNUMBER(D13)),D13-C13,"") -> 67 | L13: =IF(AND(ISNUMBER(D13),ISNUMBER(E13)),E13-D13,"") | M13: =IF(AND(ISNUMBER(E13),ISNUMBER(F13)),F13-E13,"") | N13: =IF(AND(ISNUMBER(C13),ISNUMBER(F13)),F13-C13,"") -> 118
A14: 13 | B14: 57 | C14: 45734 | D14: 45763 | E14: 45779 | F14: 45880 | G14: AVF | H14: טרם התחיל | I14: המתנה לחדר ניתוח | K14: =IF(AND(ISNUMBER(C14),ISNUMBER(D14)),D14-C14,"") -> 29 | L14: =IF(AND(ISNUMBER(D14),ISNUMBER(E14)),E14-D14,"") -> 16 | M14: =IF(AND(ISNUMBER(E14),ISNUMBER(F14)),F14-E14,"") -> 101 | N14: =IF(AND(ISNUMBER(C14),ISNUMBER(F14)),F14-C14,"") -> 146
A15: 14 | B15: 72 | C15: 45690 | D15: 45738 | E15: 45752 | F15: 45892 | G15: AVF | H15: צנתר | I15: המתנה לחדר ניתוח | J15: הגיע בצום ונשלח הביתה, נותח בשבוע שלאחר מכן | K15: =IF(AND(ISNUMBER(C15),ISNUMBER(D15)),D15-C15,"") -> 48 | L15: =IF(AND(ISNUMBER(D15),ISNUMBER(E15)),E15-D15,"") -> 14 | M15: =IF(AND(ISNUMBER(E15),ISNUMBER(F15)),F15-E15,"") -> 140 | N15: =IF(AND(ISNUMBER(C15),ISNUMBER(F15)),F15-C15,"") -> 202
A16: 15 | B16: 60 | C16: 45767 | D16: 45841 | E16: 45865 | F16: 45893 | G16: AVF | H16: פיסטולה | I16: אחר | J16: תיעוד חלקי ברשומה | K16: =IF(AND(ISNUMBER(C16),ISNUMBER(D16)),D16-C16,"") -> 74 | L16: =IF(AND(ISNUMBER(D16),ISNUMBER(E16)),E16-D16,"") -> 24 | M16: =IF(AND(ISNUMBER(E16),ISNUMBER(F16)),F16-E16,"") -> 28 | N16: =IF(AND(ISNUMBER(C16),ISNUMBER(F16)),F16-C16,"") -> 126
A17: 16 | B17: 60 | C17: 45776 | D17: 45807 | E17: 45819 | F17: 45893 | G17: AVF | H17: פיסטולה | I17: המתנה לחדר ניתוח | J17: ממתין ברשימה ללא תאריך במשך כחודשיים | K17: =IF(AND(ISNUMBER(C17),ISNUMBER(D17)),D17-C17,"") -> 31 | L17: =IF(AND(ISNUMBER(D17),ISNUMBER(E17)),E17-D17,"") -> 12 | M17: =IF(AND(ISNUMBER(E17),ISNUMBER(F17)),F17-E17,"") -> 74 | N17: =IF(AND(ISNUMBER(C17),ISNUMBER(F17)),F17-C17,"") -> 117
A18: 17 | B18: 72 | C18: 45750 | D18: 45768 | E18: 45782 | F18: 45898 | G18: AVF | H18: צנתר | I18: המתנה לחדר ניתוח | K18: =IF(AND(ISNUMBER(C18),ISNUMBER(D18)),D18-C18,"") -> 18 | L18: =IF(AND(ISNUMBER(D18),ISNUMBER(E18)),E18-D18,"") -> 14 | M18: =IF(AND(ISNUMBER(E18),ISNUMBER(F18)),F18-E18,"") -> 116 | N18: =IF(AND(ISNUMBER(C18),ISNUMBER(F18)),F18-C18,"") -> 148
A19: 18 | B19: 71 | C19: 45822 | D19: 45858 | E19: 45867 | F19: 45898 | G19: AVF | H19: צנתר | I19: הפניה מאוחרת מנפרולוגיה | J19: התחיל דיאליזה דחופה במהלך אשפוז, לפני המיפוי | K19: =IF(AND(ISNUMBER(C19),ISNUMBER(D19)),D19-C19,"") -> 36 | L19: =IF(AND(ISNUMBER(D19),ISNUMBER(E19)),E19-D19,"") -> 9 | M19: =IF(AND(ISNUMBER(E19),ISNUMBER(F19)),F19-E19,"") -> 31 | N19: =IF(AND(ISNUMBER(C19),ISNUMBER(F19)),F19-C19,"") -> 76
A20: 19 | B20: 50 | C20: 45798 | D20: 45824 | E20: 45851 | F20: 45900 | G20: AVF | H20: טרם התחיל | I20: אחר | J20: מיפוי בוצע בקהילה, תאריך לא ידוע | K20: =IF(AND(ISNUMBER(C20),ISNUMBER(D20)),D20-C20,"") -> 26 | L20: =IF(AND(ISNUMBER(D20),ISNUMBER(E20)),E20-D20,"") -> 27 | M20: =IF(AND(ISNUMBER(E20),ISNUMBER(F20)),F20-E20,"") -> 49 | N20: =IF(AND(ISNUMBER(C20),ISNUMBER(F20)),F20-C20,"") -> 102
A21: 20 | B21: 61 | C21: 45831 | D21: 45854 | E21: 45863 | F21: 45906 | G21: AVF | H21: צנתר | I21: הפניה מאוחרת מנפרולוגיה | J21: התחיל דיאליזה דחופה במהלך אשפוז, לפני המיפוי | K21: =IF(AND(ISNUMBER(C21),ISNUMBER(D21)),D21-C21,"") -> 23 | L21: =IF(AND(ISNUMBER(D21),ISNUMBER(E21)),E21-D21,"") -> 9 | M21: =IF(AND(ISNUMBER(E21),ISNUMBER(F21)),F21-E21,"") -> 43 | N21: =IF(AND(ISNUMBER(C21),ISNUMBER(F21)),F21-C21,"") -> 75
A22: 21 | B22: 71 | C22: 45763 | D22: 45777 | E22: 45806 | F22: 45906 | G22: AVF | H22: פיסטולה | I22: המתנה לחדר ניתוח | J22: נדחה פעם אחת מרשימת הניתוחים בשל ניתוח דחוף | K22: =IF(AND(ISNUMBER(C22),ISNUMBER(D22)),D22-C22,"") -> 14 | L22: =IF(AND(ISNUMBER(D22),ISNUMBER(E22)),E22-D22,"") -> 29 | M22: =IF(AND(ISNUMBER(E22),ISNUMBER(F22)),F22-E22,"") -> 100 | N22: =IF(AND(ISNUMBER(C22),ISNUMBER(F22)),F22-C22,"") -> 143
A23: 22 | B23: 60 | C23: 45811 | D23: 45857 | E23: 45877 | F23: 45910 | G23: AVF | H23: צנתר | I23: המתנה למיפוי | J23: מיפוי חוזר, הקודם לא היה בתוקף | K23: =IF(AND(ISNUMBER(C23),ISNUMBER(D23)),D23-C23,"") -> 46 | L23: =IF(AND(ISNUMBER(D23),ISNUMBER(E23)),E23-D23,"") -> 20 | M23: =IF(AND(ISNUMBER(E23),ISNUMBER(F23)),F23-E23,"") -> 33 | N23: =IF(AND(ISNUMBER(C23),ISNUMBER(F23)),F23-C23,"") -> 99
A24: 23 | B24: 70 | C24: 45731 | D24: 45801 | E24: 45818 | F24: 45910 | G24: AVF | H24: צנתר | I24: ביטול ניתוח | J24: ניתוח בוטל ביום הניתוח ונקבע מחדש | K24: =IF(AND(ISNUMBER(C24),ISNUMBER(D24)),D24-C24,"") -> 70 | L24: =IF(AND(ISNUMBER(D24),ISNUMBER(E24)),E24-D24,"") -> 17 | M24: =IF(AND(ISNUMBER(E24),ISNUMBER(F24)),F24-E24,"") -> 92 | N24: =IF(AND(ISNUMBER(C24),ISNUMBER(F24)),F24-C24,"") -> 179
A25: 24 | B25: 45 | C25: 45751 | D25: 45779 | E25: 45808 | F25: 45911 | G25: AVF | H25: צנתר | I25: בירור/הכנה רפואית | J25: נדחה בבוקר הניתוח: בדיקות טרום ניתוח לא בתוקף | K25: =IF(AND(ISNUMBER(C25),ISNUMBER(D25)),D25-C25,"") -> 28 | L25: =IF(AND(ISNUMBER(D25),ISNUMBER(E25)),E25-D25,"") -> 29 | M25: =IF(AND(ISNUMBER(E25),ISNUMBER(F25)),F25-E25,"") -> 103 | N25: =IF(AND(ISNUMBER(C25),ISNUMBER(F25)),F25-C25,"") -> 160
A26: 25 | B26: 66 | C26: 45784 | D26: 45822 | E26: 45839 | F26: 45914 | G26: AVF | H26: פיסטולה | I26: המתנה לחדר ניתוח | K26: =IF(AND(ISNUMBER(C26),ISNUMBER(D26)),D26-C26,"") -> 38 | L26: =IF(AND(ISNUMBER(D26),ISNUMBER(E26)),E26-D26,"") -> 17 | M26: =IF(AND(ISNUMBER(E26),ISNUMBER(F26)),F26-E26,"") -> 75 | N26: =IF(AND(ISNUMBER(C26),ISNUMBER(F26)),F26-C26,"") -> 130
A27: 26 | B27: 85 | C27: 45791 | D27: 45844 | E27: 45856 | F27: 45916 | G27: AVF | H27: פיסטולה | I27: המתנה לחדר ניתוח | J27: נדחה פעמיים מרשימת הניתוחים | K27: =IF(AND(ISNUMBER(C27),ISNUMBER(D27)),D27-C27,"") -> 53 | L27: =IF(AND(ISNUMBER(D27),ISNUMBER(E27)),E27-D27,"") -> 12 | M27: =IF(AND(ISNUMBER(E27),ISNUMBER(F27)),F27-E27,"") -> 60 | N27: =IF(AND(ISNUMBER(C27),ISNUMBER(F27)),F27-C27,"") -> 125
A28: 27 | B28: 54 | C28: 45764 | D28: 45807 | E28: 45828 | F28: 45919 | G28: AVF | H28: צנתר | I28: המתנה לחדר ניתוח | K28: =IF(AND(ISNUMBER(C28),ISNUMBER(D28)),D28-C28,"") -> 43 | L28: =IF(AND(ISNUMBER(D28),ISNUMBER(E28)),E28-D28,"") -> 21 | M28: =IF(AND(ISNUMBER(E28),ISNUMBER(F28)),F28-E28,"") -> 91 | N28: =IF(AND(ISNUMBER(C28),ISNUMBER(F28)),F28-C28,"") -> 155
A29: 28 | B29: 57 | C29: 45840 | D29: 45869 | E29: 45887 | F29: 45920 | G29: AVF | H29: צנתר | I29: הפניה מאוחרת מנפרולוגיה | J29: הופנה כשכבר היה קרוב לדיאליזה | K29: =IF(AND(ISNUMBER(C29),ISNUMBER(D29)),D29-C29,"") -> 29 | L29: =IF(AND(ISNUMBER(D29),ISNUMBER(E29)),E29-D29,"") -> 18 | M29: =IF(AND(ISNUMBER(E29),ISNUMBER(F29)),F29-E29,"") -> 33 | N29: =IF(AND(ISNUMBER(C29),ISNUMBER(F29)),F29-C29,"") -> 80
A30: 29 | B30: 63 | C30: 45739 | D30: 45766 | E30: 45798 | F30: 45921 | G30: AVF | H30: פיסטולה | I30: המתנה לחדר ניתוח | J30: נדחה פעמיים מרשימת הניתוחים | K30: =IF(AND(ISNUMBER(C30),ISNUMBER(D30)),D30-C30,"") -> 27 | L30: =IF(AND(ISNUMBER(D30),ISNUMBER(E30)),E30-D30,"") -> 32 | M30: =IF(AND(ISNUMBER(E30),ISNUMBER(F30)),F30-E30,"") -> 123 | N30: =IF(AND(ISNUMBER(C30),ISNUMBER(F30)),F30-C30,"") -> 182
A31: 30 | B31: 63 | C31: 45789 | D31: 45815 | E31: 45827 | F31: 45921 | G31: AVF | H31: צנתר | I31: ביטול ניתוח | J31: בוטל בתקופת הפעילות המצומצמת, נקבע מחדש | K31: =IF(AND(ISNUMBER(C31),ISNUMBER(D31)),D31-C31,"") -> 26 | L31: =IF(AND(ISNUMBER(D31),ISNUMBER(E31)),E31-D31,"") -> 12 | M31: =IF(AND(ISNUMBER(E31),ISNUMBER(F31)),F31-E31,"") -> 94 | N31: =IF(AND(ISNUMBER(C31),ISNUMBER(F31)),F31-C31,"") -> 132
A32: 31 | B32: 59 | C32: 45789 | D32: 45825 | E32: 45838 | F32: 45933 | G32: AVF | H32: צנתר | I32: בירור/הכנה רפואית | J32: נדחה בבוקר הניתוח: בדיקות טרום ניתוח לא בתוקף | K32: =IF(AND(ISNUMBER(C32),ISNUMBER(D32)),D32-C32,"") -> 36 | L32: =IF(AND(ISNUMBER(D32),ISNUMBER(E32)),E32-D32,"") -> 13 | M32: =IF(AND(ISNUMBER(E32),ISNUMBER(F32)),F32-E32,"") -> 95 | N32: =IF(AND(ISNUMBER(C32),ISNUMBER(F32)),F32-C32,"") -> 144
A33: 32 | B33: 39 | C33: 45806 | D33: 45856 | E33: 45890 | F33: 45940 | G33: AVF | H33: פיסטולה | I33: דחייה ע"י המטופל | J33: סירב בתחילה לפיסטולה, הסכים לאחר התחלת דיאליזה | K33: =IF(AND(ISNUMBER(C33),ISNUMBER(D33)),D33-C33,"") -> 50 | L33: =IF(AND(ISNUMBER(D33),ISNUMBER(E33)),E33-D33,"") -> 34 | M33: =IF(AND(ISNUMBER(E33),ISNUMBER(F33)),F33-E33,"") -> 50 | N33: =IF(AND(ISNUMBER(C33),ISNUMBER(F33)),F33-C33,"") -> 134
A34: 33 | B34: 77 | C34: 45821 | D34: 45846 | E34: 45889 | F34: 45947 | G34: AVG (שתל) | H34: צנתר | I34: המתנה לתור במרפאה | K34: =IF(AND(ISNUMBER(C34),ISNUMBER(D34)),D34-C34,"") -> 25 | L34: =IF(AND(ISNUMBER(D34),ISNUMBER(E34)),E34-D34,"") -> 43 | M34: =IF(AND(ISNUMBER(E34),ISNUMBER(F34)),F34-E34,"") -> 58 | N34: =IF(AND(ISNUMBER(C34),ISNUMBER(F34)),F34-C34,"") -> 126
A35: 34 | B35: 79 | C35: 45772 | D35: 45790 | E35: 45828 | F35: 45957 | G35: AVF | H35: פיסטולה | I35: המתנה לחדר ניתוח | J35: נדחה פעם אחת מרשימת הניתוחים בשל ניתוח דחוף | K35: =IF(AND(ISNUMBER(C35),ISNUMBER(D35)),D35-C35,"") -> 18 | L35: =IF(AND(ISNUMBER(D35),ISNUMBER(E35)),E35-D35,"") -> 38 | M35: =IF(AND(ISNUMBER(E35),ISNUMBER(F35)),F35-E35,"") -> 129 | N35: =IF(AND(ISNUMBER(C35),ISNUMBER(F35)),F35-C35,"") -> 185
A36: 35 | B36: 73 | C36: 45872 | D36: 45891 | E36: 45907 | F36: 45963 | G36: AVF | H36: צנתר | I36: דחייה ע"י המטופל | J36: סירב בתחילה לפיסטולה, הסכים לאחר התחלת דיאליזה | K36: =IF(AND(ISNUMBER(C36),ISNUMBER(D36)),D36-C36,"") -> 19 | L36: =IF(AND(ISNUMBER(D36),ISNUMBER(E36)),E36-D36,"") -> 16 | M36: =IF(AND(ISNUMBER(E36),ISNUMBER(F36)),F36-E36,"") -> 56 | N36: =IF(AND(ISNUMBER(C36),ISNUMBER(F36)),F36-C36,"") -> 91
A37: 36 | B37: 51 | C37: 45836 | D37: 45886 | E37: 45938 | F37: 45966 | G37: AVF | H37: טרם התחיל | I37: המתנה למיפוי | K37: =IF(AND(ISNUMBER(C37),ISNUMBER(D37)),D37-C37,"") -> 50 | L37: =IF(AND(ISNUMBER(D37),ISNUMBER(E37)),E37-D37,"") -> 52 | M37: =IF(AND(ISNUMBER(E37),ISNUMBER(F37)),F37-E37,"") -> 28 | N37: =IF(AND(ISNUMBER(C37),ISNUMBER(F37)),F37-C37,"") -> 130
A38: 37 | B38: 65 | C38: 45875 | D38: 45900 | E38: 45928 | F38: 45973 | G38: AVF | H38: צנתר | I38: הפניה מאוחרת מנפרולוגיה | J38: הפניה מהקהילה | K38: =IF(AND(ISNUMBER(C38),ISNUMBER(D38)),D38-C38,"") -> 25 | L38: =IF(AND(ISNUMBER(D38),ISNUMBER(E38)),E38-D38,"") -> 28 | M38: =IF(AND(ISNUMBER(E38),ISNUMBER(F38)),F38-E38,"") -> 45 | N38: =IF(AND(ISNUMBER(C38),ISNUMBER(F38)),F38-C38,"") -> 98
A39: 38 | B39: 53 | C39: 45835 | D39: 45881 | E39: 45904 | F39: 45973 | G39: AVF | H39: צנתר | I39: דחייה ע"י המטופל | J39: המטופל ביקש לדחות את הניתוח | K39: =IF(AND(ISNUMBER(C39),ISNUMBER(D39)),D39-C39,"") -> 46 | L39: =IF(AND(ISNUMBER(D39),ISNUMBER(E39)),E39-D39,"") -> 23 | M39: =IF(AND(ISNUMBER(E39),ISNUMBER(F39)),F39-E39,"") -> 69 | N39: =IF(AND(ISNUMBER(C39),ISNUMBER(F39)),F39-C39,"") -> 138
A40: 39 | B40: 70 | C40: 45912 | D40: 45938 | E40: 45957 | F40: 45987 | G40: AVF | H40: צנתר | I40: הפניה מאוחרת מנפרולוגיה | K40: =IF(AND(ISNUMBER(C40),ISNUMBER(D40)),D40-C40,"") -> 26 | L40: =IF(AND(ISNUMBER(D40),ISNUMBER(E40)),E40-D40,"") -> 19 | M40: =IF(AND(ISNUMBER(E40),ISNUMBER(F40)),F40-E40,"") -> 30 | N40: =IF(AND(ISNUMBER(C40),ISNUMBER(F40)),F40-C40,"") -> 75
...

Sheet סיכום
A1: סיכום זמנים במסלול (בימים)
A3: שלב | B3: מספר מטופלים | C3: חציון | D3: ממוצע | E3: מינימום | F3: מקסימום
A4: הפניה → מיפוי | B4: =COUNT(נתונים!K2:K151) -> 80 | C4: =IF(COUNT(נתונים!K2:K151)=0,"",MEDIAN(נתונים!K2:K151)) -> 32 | D4: =IF(COUNT(נתונים!K2:K151)=0,"",AVERAGE(נתונים!K2:K151)) -> 35.3 | E4: =IF(COUNT(נתונים!K2:K151)=0,"",MIN(נתונים!K2:K151)) -> 11 | F4: =IF(COUNT(נתונים!K2:K151)=0,"",MAX(נתונים!K2:K151)) -> 90
A5: מיפוי → מרפאה | B5: =COUNT(נתונים!L2:L151) -> 78 | C5: =IF(COUNT(נתונים!L2:L151)=0,"",MEDIAN(נתונים!L2:L151)) -> 18.5 | D5: =IF(COUNT(נתונים!L2:L151)=0,"",AVERAGE(נתונים!L2:L151)) -> 21.294872 | E5: =IF(COUNT(נתונים!L2:L151)=0,"",MIN(נתונים!L2:L151)) -> 5 | F5: =IF(COUNT(נתונים!L2:L151)=0,"",MAX(נתונים!L2:L151)) -> 80
A6: מרפאה → ניתוח | B6: =COUNT(נתונים!M2:M151) -> 82 | C6: =IF(COUNT(נתונים!M2:M151)=0,"",MEDIAN(נתונים!M2:M151)) -> 68.5 | D6: =IF(COUNT(נתונים!M2:M151)=0,"",AVERAGE(נתונים!M2:M151)) -> 72.463415 | E6: =IF(COUNT(נתונים!M2:M151)=0,"",MIN(נתונים!M2:M151)) -> 12 | F6: =IF(COUNT(נתונים!M2:M151)=0,"",MAX(נתונים!M2:M151)) -> 188
A7: סה"כ: הפניה → ניתוח | B7: =COUNT(נתונים!N2:N151) -> 84 | C7: =IF(COUNT(נתונים!N2:N151)=0,"",MEDIAN(נתונים!N2:N151)) -> 129 | D7: =IF(COUNT(נתונים!N2:N151)=0,"",AVERAGE(נתונים!N2:N151)) -> 128.32143 | E7: =IF(COUNT(נתונים!N2:N151)=0,"",MIN(נתונים!N2:N151)) -> 32 | F7: =IF(COUNT(נתונים!N2:N151)=0,"",MAX(נתונים!N2:N151)) -> 277
A10: התחלת דיאליזה
A11: סוג | B11: מספר | C11: אחוז מתוך מי שהתחילו דיאליזה
A12: פיסטולה | B12: =COUNTIF(נתונים!$H$2:$H$151,A12) -> 26 | C12: =IF(SUM($B$12:$B$13)=0,"",B12/SUM($B$12:$B$13)) -> 0.37142857
A13: צנתר | B13: =COUNTIF(נתונים!$H$2:$H$151,A13) -> 44 | C13: =IF(SUM($B$12:$B$13)=0,"",B13/SUM($B$12:$B$13)) -> 0.62857143
A14: טרם התחיל | B14: =COUNTIF(נתונים!$H$2:$H$151,A14) -> 14 | C14: —
A17: סיבות עיכוב עיקריות
A18: סיבה | B18: מספר | C18: אחוז
A19: המתנה למיפוי | B19: =COUNTIF(נתונים!$I$2:$I$151,A19) -> 12 | C19: =IF(SUM($B$19:$B$27)=0,"",B19/SUM($B$19:$B$27)) -> 0.14285714
A20: המתנה לתור במרפאה | B20: =COUNTIF(נתונים!$I$2:$I$151,A20) -> 4 | C20: =IF(SUM($B$19:$B$27)=0,"",B20/SUM($B$19:$B$27)) -> 0.047619048
A21: המתנה לחדר ניתוח | B21: =COUNTIF(נתונים!$I$2:$I$151,A21) -> 25 | C21: =IF(SUM($B$19:$B$27)=0,"",B21/SUM($B$19:$B$27)) -> 0.29761905
A22: הפניה מאוחרת מנפרולוגיה | B22: =COUNTIF(נתונים!$I$2:$I$151,A22) -> 13 | C22: =IF(SUM($B$19:$B$27)=0,"",B22/SUM($B$19:$B$27)) -> 0.1547619
A23: בירור/הכנה רפואית | B23: =COUNTIF(נתונים!$I$2:$I$151,A23) -> 8 | C23: =IF(SUM($B$19:$B$27)=0,"",B23/SUM($B$19:$B$27)) -> 0.095238095
A24: דחייה ע"י המטופל | B24: =COUNTIF(נתונים!$I$2:$I$151,A24) -> 7 | C24: =IF(SUM($B$19:$B$27)=0,"",B24/SUM($B$19:$B$27)) -> 0.083333333
A25: ביטול ניתוח | B25: =COUNTIF(נתונים!$I$2:$I$151,A25) -> 6 | C25: =IF(SUM($B$19:$B$27)=0,"",B25/SUM($B$19:$B$27)) -> 0.071428571
A26: אחר | B26: =COUNTIF(נתונים!$I$2:$I$151,A26) -> 4 | C26: =IF(SUM($B$19:$B$27)=0,"",B26/SUM($B$19:$B$27)) -> 0.047619048
A27: ללא עיכוב משמעותי | B27: =COUNTIF(נתונים!$I$2:$I$151,A27) -> 5 | C27: =IF(SUM($B$19:$B$27)=0,"",B27/SUM($B$19:$B$27)) -> 0.05952381

Sheet רשימות
A1: סוג גישה | B1: התחלת דיאליזה | C1: סיבת עיכוב
A2: AVF | B2: פיסטולה | C2: המתנה למיפוי
A3: AVG (שתל) | B3: צנתר | C3: המתנה לתור במרפאה
B4: טרם התחיל | C4: המתנה לחדר ניתוח
C5: הפניה מאוחרת מנפרולוגיה
C6: בירור/הכנה רפואית
C7: דחייה ע"י המטופל
C8: ביטול ניתוח
C9: אחר
C10: ללא עיכוב משמעותי
