Workbook

Sheet הוראות
A1: הוראות שימוש בקובץ
A2: 1. כל שאלון מלא = שורה אחת בגיליון 'נתונים', החל משורה 3. מקלידים רק בעמודות הלבנות (A עד AG).
A3: 2. העמודות האפורות (AH והלאה) מחושבות אוטומטית – לא להקליד בהן.
A4: 3. את הקודים לכל שאלה (למשל 1=בן, 2=בת) מוצאים בגיליון 'קידוד'. תשובה חסרה – משאירים את התא ריק.
A5: 4. התוצאות מתעדכנות לבד בגיליונות: 'תיאורי' (ממוצעים ומאפייני מדגם), 'מתאמים' (שאלת המחקר), 'השוואת קבוצות' (טיפוסיים מול מתקשים), 'מהימנות' (אלפא).
A6: 5. שאלון שחסר בו היגד בסולם מסוים לא ייכלל בממוצע של אותו סולם (רק שאלונים מלאים).
A7: 6. מילוי ב-Google Forms: הגדר/י את אפשרויות התשובה כמספרים (1–5) כדי שהייצוא יהיה מוכן להדבקה כאן, בסדר העמודות שבגיליון 'קידוד'.
A9: גודל מדגם מומלץ
A10: • לבדיקת מתאם בינוני (r=.30, α=.05, עוצמה .80) נדרשים לפחות 85 תלמידים.
A11: • להשוואת קבוצות (הבדל בינוני, d=.50) נדרשים כ-64 בכל קבוצה; להבדל בינוני-גדול (d=.60) כ-45 בכל קבוצה.
A12: • יעד: 120–150 שאלונים מלאים, מתוכם לפחות 40–45 תלמידים מתקשים. להפיץ לכ-180–200 תלמידים, כי חלק לא יחזרו או יהיו חלקיים.
A14: דוגמה לשורה מלאה (להמחשה בלבד – לא להקליד אותה בגיליון 'נתונים'):
A15: ID | B15: GENDER | C15: GRADE | D15: AGE | E15: SCI | F15: DIAG | G15: SUPPORT | H15: C1 | I15: C2 | J15: C3 | K15: C4 | L15: C5 | M15: C6 | N15: C7 | O15: C8 | P15: D1 | Q15: D2 | R15: D3 | S15: D4 | T15: D5 | U15: D6 | V15: D7 | W15: D8 | X15: D9 | Y15: D10 | Z15: E1 | AA15: E2 | AB15: E3 | AC15: E4 | AD15: E5 | AE15: E6 | AF15: E7 | AG15: E8
A16: 1 | B16: 2 | C16: 2 | D16: 13 | E16: 3 | F16: 2 | G16: 2 | H16: 4 | I16: 4 | J16: 3 | K16: 4 | L16: 3 | M16: 4 | N16: 4 | O16: 5 | P16: 4 | Q16: 3 | R16: 4 | S16: 3 | T16: 4 | U16: 4 | V16: 2 | W16: 2 | X16: 3 | Y16: 2 | Z16: 4 | AA16: 3 | AB16: 4 | AC16: 5 | AD16: 4 | AE16: 4 | AF16: 4 | AG16: 3
A17: פירוש: תלמידה בכיתה ח', בת 13, ציון 70–84 במדעים, בלי אבחון ובלי שילוב (= טיפוסית), ואחריהם 26 תשובות בסולם 1–5.
A19: הערה: בגיליון 'נתונים' הוקלדו 102 שאלונים (מתוך 120 שהופצו: 35 בכיתה ז', 34 בכיתה ח', 33 בכיתה ט'). ארבעה שאלונים חסרים היגד אחד ולכן אינם נכללים בממוצע של אותו סולם.

Sheet נתונים
A1: ID | B1: GENDER | C1: GRADE | D1: AGE | E1: SCI | F1: DIAG | G1: SUPPORT | H1: C1 | I1: C2 | J1: C3 | K1: C4 | L1: C5 | M1: C6 | N1: C7 | O1: C8 | P1: D1 | Q1: D2 | R1: D3 | S1: D4 | T1: D5 | U1: D6 | V1: D7 | W1: D8 | X1: D9 | Y1: D10 | Z1: E1 | AA1: E2 | AB1: E3 | AC1: E4 | AD1: E5 | AE1: E6 | AF1: E7 | AG1: E8 | AH1: D7R | AI1: D8R | AJ1: D9R | AK1: D10R | AL1: CRE_SUM | AM1: DM_SUM | AN1: ENJ_SUM | AO1: CRE | AP1: DM | AQ1: ENJ | AR1: GROUP | AS1: GROUP_TXT | AT1: CRE_T | AU1: CRE_S | AV1: DM_T | AW1: DM_S | AX1: ENJ_T | AY1: ENJ_S
A2: מס' שאלון | B2: מגדר | C2: כיתה | D2: גיל | E2: ציון מדעים | F2: אבחון | G2: תמיכה/שילוב | H2: יצירתיות 1 | I2: יצירתיות 2 | J2: יצירתיות 3 | K2: יצירתיות 4 | L2: יצירתיות 5 | M2: יצירתיות 6 | N2: יצירתיות 7 | O2: יצירתיות 8 | P2: החלטות 1 | Q2: החלטות 2 | R2: החלטות 3 | S2: החלטות 4 | T2: החלטות 5 | U2: החלטות 6 | V2: החלטות 7 (הפוך) | W2: החלטות 8 (הפוך) | X2: החלטות 9 (הפוך) | Y2: החלטות 10 (הפוך) | Z2: הנאה 1 | AA2: הנאה 2 | AB2: הנאה 3 | AC2: הנאה 4 | AD2: הנאה 5 | AE2: הנאה 6 | AF2: הנאה 7 | AG2: הנאה 8 | AH2: החלטות 7 אחרי היפוך | AI2: החלטות 8 אחרי היפוך | AJ2: החלטות 9 אחרי היפוך | AK2: החלטות 10 אחרי היפוך | AL2: סכום יצירתיות | AM2: סכום החלטות | AN2: סכום הנאה | AO2: ממוצע יצירתיות | AP2: ממוצע קבלת החלטות | AQ2: ממוצע הנאה | AR2: קבוצה (1=טיפוסי, 2=מתקשה) | AS2: קבוצה | AT2: יצירתיות - טיפוסי | AU2: יצירתיות - מתקשה | AV2: החלטות - טיפוסי | AW2: החלטות - מתקשה | AX2: הנאה - טיפוסי | AY2: הנאה - מתקשה
A3: 1 | B3: 2 | C3: 3 | D3: 14 | E3: 2 | F3: 1 | G3: 1 | H3: 3 | I3: 2 | J3: 2 | K3: 3 | L3: 2 | M3: 2 | N3: 1 | O3: 3 | P3: 4 | Q3: 1 | R3: 3 | S3: 3 | T3: 1 | U3: 2 | V3: 3 | W3: 5 | X3: 4 | Y3: 3 | Z3: 3 | AA3: 4 | AB3: 2 | AC3: 4 | AD3: 3 | AE3: 4 | AF3: 3 | AG3: 3 | AH3: =IF(V3="","",6-V3) -> 3 | AI3: =IF(W3="","",6-W3) -> 1 | AJ3: =IF(X3="","",6-X3) -> 2 | AK3: =IF(Y3="","",6-Y3) -> 3 | AL3: =IF(COUNT(H3:O3)=8,SUM(H3:O3),"") -> 18 | AM3: =IF(COUNT(P3:U3,AH3:AK3)=10,SUM(P3:U3,AH3:AK3),"") -> 23 | AN3: =IF(COUNT(Z3:AG3)=8,SUM(Z3:AG3),"") -> 26 | AO3: =IF(AL3="","",AL3/8) -> 2.25 | AP3: =IF(AM3="","",AM3/10) -> 2.3 | AQ3: =IF(AN3="","",AN3/8) -> 3.25 | AR3: =IF(A3="","",IF(OR(F3=1,G3=1,AND(E3<>"",E3<=2)),2,IF(AND(E3>=3,G3=2,OR(F3=2,F3=3)),1,""))) -> 2 | AS3: =IF(AR3=1,"טיפוסי",IF(AR3=2,"מתקשה","")) -> מתקשה | AT3: =IF(AR3=1,AO3,"") | AU3: =IF(AR3=2,AO3,"") -> 2.25 | AV3: =IF(AR3=1,AP3,"") | AW3: =IF(AR3=2,AP3,"") -> 2.3 | AX3: =IF(AR3=1,AQ3,"") | AY3: =IF(AR3=2,AQ3,"") -> 3.25
A4: 2 | B4: 1 | C4: 3 | D4: 15 | E4: 4 | F4: 2 | G4: 2 | H4: 3 | I4: 5 | J4: 4 | K4: 5 | L4: 3 | M4: 4 | N4: 5 | O4: 4 | P4: 4 | Q4: 5 | R4: 2 | S4: 3 | T4: 3 | U4: 3 | V4: 2 | W4: 2 | X4: 4 | Y4: 3 | Z4: 4 | AA4: 4 | AB4: 4 | AC4: 3 | AD4: 3 | AE4: 5 | AF4: 5 | AG4: 4 | AH4: =IF(V4="","",6-V4) -> 4 | AI4: =IF(W4="","",6-W4) -> 4 | AJ4: =IF(X4="","",6-X4) -> 2 | AK4: =IF(Y4="","",6-Y4) -> 3 | AL4: =IF(COUNT(H4:O4)=8,SUM(H4:O4),"") -> 33 | AM4: =IF(COUNT(P4:U4,AH4:AK4)=10,SUM(P4:U4,AH4:AK4),"") -> 33 | AN4: =IF(COUNT(Z4:AG4)=8,SUM(Z4:AG4),"") -> 32 | AO4: =IF(AL4="","",AL4/8) -> 4.125 | AP4: =IF(AM4="","",AM4/10) -> 3.3 | AQ4: =IF(AN4="","",AN4/8) -> 4 | AR4: =IF(A4="","",IF(OR(F4=1,G4=1,AND(E4<>"",E4<=2)),2,IF(AND(E4>=3,G4=2,OR(F4=2,F4=3)),1,""))) -> 1 | AS4: =IF(AR4=1,"טיפוסי",IF(AR4=2,"מתקשה","")) -> טיפוסי | AT4: =IF(AR4=1,AO4,"") -> 4.125 | AU4: =IF(AR4=2,AO4,"") | AV4: =IF(AR4=1,AP4,"") -> 3.3 | AW4: =IF(AR4=2,AP4,"") | AX4: =IF(AR4=1,AQ4,"") -> 4 | AY4: =IF(AR4=2,AQ4,"")
A5: 3 | B5: 2 | C5: 1 | D5: 13 | E5: 3 | F5: 2 | G5: 2 | H5: 3 | I5: 4 | J5: 4 | K5: 3 | L5: 3 | M5: 5 | N5: 2 | O5: 4 | P5: 3 | Q5: 2 | R5: 2 | S5: 3 | T5: 3 | U5: 3 | V5: 3 | W5: 5 | X5: 3 | Y5: 2 | Z5: 3 | AA5: 4 | AB5: 4 | AC5: 5 | AD5: 3 | AE5: 4 | AF5: 5 | AG5: 3 | AH5: =IF(V5="","",6-V5) -> 3 | AI5: =IF(W5="","",6-W5) -> 1 | AJ5: =IF(X5="","",6-X5) -> 3 | AK5: =IF(Y5="","",6-Y5) -> 4 | AL5: =IF(COUNT(H5:O5)=8,SUM(H5:O5),"") -> 28 | AM5: =IF(COUNT(P5:U5,AH5:AK5)=10,SUM(P5:U5,AH5:AK5),"") -> 27 | AN5: =IF(COUNT(Z5:AG5)=8,SUM(Z5:AG5),"") -> 31 | AO5: =IF(AL5="","",AL5/8) -> 3.5 | AP5: =IF(AM5="","",AM5/10) -> 2.7 | AQ5: =IF(AN5="","",AN5/8) -> 3.875 | AR5: =IF(A5="","",IF(OR(F5=1,G5=1,AND(E5<>"",E5<=2)),2,IF(AND(E5>=3,G5=2,OR(F5=2,F5=3)),1,""))) -> 1 | AS5: =IF(AR5=1,"טיפוסי",IF(AR5=2,"מתקשה","")) -> טיפוסי | AT5: =IF(AR5=1,AO5,"") -> 3.5 | AU5: =IF(AR5=2,AO5,"") | AV5: =IF(AR5=1,AP5,"") -> 2.7 | AW5: =IF(AR5=2,AP5,"") | AX5: =IF(AR5=1,AQ5,"") -> 3.875 | AY5: =IF(AR5=2,AQ5,"")
A6: 4 | B6: 2 | C6: 1 | D6: 12 | E6: 1 | F6: 1 | G6: 1 | H6: 2 | I6: 2 | J6: 4 | K6: 3 | L6: 1 | M6: 4 | N6: 2 | O6: 2 | P6: 1 | Q6: 2 | R6: 3 | S6: 3 | T6: 2 | U6: 2 | V6: 5 | W6: 3 | X6: 5 | Y6: 4 | Z6: 4 | AA6: 2 | AB6: 3 | AC6: 4 | AD6: 3 | AE6: 4 | AF6: 3 | AG6: 4 | AH6: =IF(V6="","",6-V6) -> 1 | AI6: =IF(W6="","",6-W6) -> 3 | AJ6: =IF(X6="","",6-X6) -> 1 | AK6: =IF(Y6="","",6-Y6) -> 2 | AL6: =IF(COUNT(H6:O6)=8,SUM(H6:O6),"") -> 20 | AM6: =IF(COUNT(P6:U6,AH6:AK6)=10,SUM(P6:U6,AH6:AK6),"") -> 20 | AN6: =IF(COUNT(Z6:AG6)=8,SUM(Z6:AG6),"") -> 27 | AO6: =IF(AL6="","",AL6/8) -> 2.5 | AP6: =IF(AM6="","",AM6/10) -> 2 | AQ6: =IF(AN6="","",AN6/8) -> 3.375 | AR6: =IF(A6="","",IF(OR(F6=1,G6=1,AND(E6<>"",E6<=2)),2,IF(AND(E6>=3,G6=2,OR(F6=2,F6=3)),1,""))) -> 2 | AS6: =IF(AR6=1,"טיפוסי",IF(AR6=2,"מתקשה","")) -> מתקשה | AT6: =IF(AR6=1,AO6,"") | AU6: =IF(AR6=2,AO6,"") -> 2.5 | AV6: =IF(AR6=1,AP6,"") | AW6: =IF(AR6=2,AP6,"") -> 2 | AX6: =IF(AR6=1,AQ6,"") | AY6: =IF(AR6=2,AQ6,"") -> 3.375
A7: 5 | B7: 1 | C7: 1 | D7: 12 | E7: 3 | F7: 2 | G7: 2 | H7: 5 | I7: 5 | J7: 5 | K7: 5 | L7: 5 | M7: 5 | N7: 5 | O7: 5 | P7: 2 | Q7: 2 | R7: 1 | S7: 2 | T7: 4 | U7: 3 | V7: 4 | W7: 5 | X7: 3 | Y7: 3 | Z7: 5 | AA7: 4 | AB7: 5 | AC7: 3 | AD7: 4 | AE7: 4 | AF7: 4 | AG7: 4 | AH7: =IF(V7="","",6-V7) -> 2 | AI7: =IF(W7="","",6-W7) -> 1 | AJ7: =IF(X7="","",6-X7) -> 3 | AK7: =IF(Y7="","",6-Y7) -> 3 | AL7: =IF(COUNT(H7:O7)=8,SUM(H7:O7),"") -> 40 | AM7: =IF(COUNT(P7:U7,AH7:AK7)=10,SUM(P7:U7,AH7:AK7),"") -> 23 | AN7: =IF(COUNT(Z7:AG7)=8,SUM(Z7:AG7),"") -> 33 | AO7: =IF(AL7="","",AL7/8) -> 5 | AP7: =IF(AM7="","",AM7/10) -> 2.3 | AQ7: =IF(AN7="","",AN7/8) -> 4.125 | AR7: =IF(A7="","",IF(OR(F7=1,G7=1,AND(E7<>"",E7<=2)),2,IF(AND(E7>=3,G7=2,OR(F7=2,F7=3)),1,""))) -> 1 | AS7: =IF(AR7=1,"טיפוסי",IF(AR7=2,"מתקשה","")) -> טיפוסי | AT7: =IF(AR7=1,AO7,"") -> 5 | AU7: =IF(AR7=2,AO7,"") | AV7: =IF(AR7=1,AP7,"") -> 2.3 | AW7: =IF(AR7=2,AP7,"") | AX7: =IF(AR7=1,AQ7,"") -> 4.125 | AY7: =IF(AR7=2,AQ7,"")
A8: 6 | B8: 2 | C8: 1 | D8: 13 | E8: 3 | F8: 2 | G8: 2 | H8: 3 | I8: 2 | J8: 2 | K8: 2 | L8: 5 | M8: 4 | N8: 4 | O8: 4 | P8: 5 | Q8: 5 | R8: 5 | S8: 5 | T8: 4 | U8: 4 | V8: 2 | W8: 2 | X8: 3 | Y8: 1 | Z8: 3 | AA8: 4 | AB8: 3 | AC8: 5 | AD8: 4 | AE8: 5 | AF8: 3 | AG8: 5 | AH8: =IF(V8="","",6-V8) -> 4 | AI8: =IF(W8="","",6-W8) -> 4 | AJ8: =IF(X8="","",6-X8) -> 3 | AK8: =IF(Y8="","",6-Y8) -> 5 | AL8: =IF(COUNT(H8:O8)=8,SUM(H8:O8),"") -> 26 | AM8: =IF(COUNT(P8:U8,AH8:AK8)=10,SUM(P8:U8,AH8:AK8),"") -> 44 | AN8: =IF(COUNT(Z8:AG8)=8,SUM(Z8:AG8),"") -> 32 | AO8: =IF(AL8="","",AL8/8) -> 3.25 | AP8: =IF(AM8="","",AM8/10) -> 4.4 | AQ8: =IF(AN8="","",AN8/8) -> 4 | AR8: =IF(A8="","",IF(OR(F8=1,G8=1,AND(E8<>"",E8<=2)),2,IF(AND(E8>=3,G8=2,OR(F8=2,F8=3)),1,""))) -> 1 | AS8: =IF(AR8=1,"טיפוסי",IF(AR8=2,"מתקשה","")) -> טיפוסי | AT8: =IF(AR8=1,AO8,"") -> 3.25 | AU8: =IF(AR8=2,AO8,"") | AV8: =IF(AR8=1,AP8,"") -> 4.4 | AW8: =IF(AR8=2,AP8,"") | AX8: =IF(AR8=1,AQ8,"") -> 4 | AY8: =IF(AR8=2,AQ8,"")
A9: 7 | B9: 2 | C9: 2 | D9: 13 | E9: 1 | F9: 1 | G9: 2 | H9: 3 | I9: 3 | J9: 2 | K9: 4 | L9: 3 | M9: 4 | N9: 3 | O9: 4 | P9: 4 | Q9: 3 | R9: 2 | S9: 5 | T9: 4 | U9: 1 | V9: 3 | W9: 3 | X9: 4 | Y9: 3 | Z9: 2 | AA9: 3 | AB9: 3 | AC9: 4 | AD9: 4 | AE9: 2 | AF9: 1 | AG9: 2 | AH9: =IF(V9="","",6-V9) -> 3 | AI9: =IF(W9="","",6-W9) -> 3 | AJ9: =IF(X9="","",6-X9) -> 2 | AK9: =IF(Y9="","",6-Y9) -> 3 | AL9: =IF(COUNT(H9:O9)=8,SUM(H9:O9),"") -> 26 | AM9: =IF(COUNT(P9:U9,AH9:AK9)=10,SUM(P9:U9,AH9:AK9),"") -> 30 | AN9: =IF(COUNT(Z9:AG9)=8,SUM(Z9:AG9),"") -> 21 | AO9: =IF(AL9="","",AL9/8) -> 3.25 | AP9: =IF(AM9="","",AM9/10) -> 3 | AQ9: =IF(AN9="","",AN9/8) -> 2.625 | AR9: =IF(A9="","",IF(OR(F9=1,G9=1,AND(E9<>"",E9<=2)),2,IF(AND(E9>=3,G9=2,OR(F9=2,F9=3)),1,""))) -> 2 | AS9: =IF(AR9=1,"טיפוסי",IF(AR9=2,"מתקשה","")) -> מתקשה | AT9: =IF(AR9=1,AO9,"") | AU9: =IF(AR9=2,AO9,"") -> 3.25 | AV9: =IF(AR9=1,AP9,"") | AW9: =IF(AR9=2,AP9,"") -> 3 | AX9: =IF(AR9=1,AQ9,"") | AY9: =IF(AR9=2,AQ9,"") -> 2.625
A10: 8 | B10: 2 | C10: 1 | D10: 13 | E10: 3 | F10: 2 | G10: 2 | H10: 3 | I10: 3 | J10: 3 | K10: 3 | L10: 4 | M10: 4 | N10: 4 | O10: 3 | P10: 2 | Q10: 3 | R10: 2 | S10: 2 | T10: 4 | U10: 1 | V10: 4 | W10: 4 | X10: 3 | Y10: 4 | AA10: 4 | AB10: 5 | AC10: 4 | AD10: 4 | AE10: 5 | AF10: 4 | AG10: 4 | AH10: =IF(V10="","",6-V10) -> 2 | AI10: =IF(W10="","",6-W10) -> 2 | AJ10: =IF(X10="","",6-X10) -> 3 | AK10: =IF(Y10="","",6-Y10) -> 2 | AL10: =IF(COUNT(H10:O10)=8,SUM(H10:O10),"") -> 27 | AM10: =IF(COUNT(P10:U10,AH10:AK10)=10,SUM(P10:U10,AH10:AK10),"") -> 23 | AN10: =IF(COUNT(Z10:AG10)=8,SUM(Z10:AG10),"") | AO10: =IF(AL10="","",AL10/8) -> 3.375 | AP10: =IF(AM10="","",AM10/10) -> 2.3 | AQ10: =IF(AN10="","",AN10/8) | AR10: =IF(A10="","",IF(OR(F10=1,G10=1,AND(E10<>"",E10<=2)),2,IF(AND(E10>=3,G10=2,OR(F10=2,F10=3)),1,""))) -> 1 | AS10: =IF(AR10=1,"טיפוסי",IF(AR10=2,"מתקשה","")) -> טיפוסי | AT10: =IF(AR10=1,AO10,"") -> 3.375 | AU10: =IF(AR10=2,AO10,"") | AV10: =IF(AR10=1,AP10,"") -> 2.3 | AW10: =IF(AR10=2,AP10,"") | AX10: =IF(AR10=1,AQ10,"") | AY10: =IF(AR10=2,AQ10,"")
A11: 9 | B11: 2 | C11: 3 | D11: 15 | E11: 2 | F11: 3 | G11: 2 | H11: 3 | I11: 3 | J11: 2 | K11: 4 | L11: 3 | M11: 3 | N11: 3 | O11: 4 | P11: 2 | Q11: 1 | S11: 2 | T11: 2 | U11: 3 | V11: 3 | W11: 3 | X11: 5 | Y11: 2 | Z11: 3 | AA11: 4 | AB11: 4 | AC11: 3 | AD11: 4 | AE11: 2 | AF11: 3 | AG11: 2 | AH11: =IF(V11="","",6-V11) -> 3 | AI11: =IF(W11="","",6-W11) -> 3 | AJ11: =IF(X11="","",6-X11) -> 1 | AK11: =IF(Y11="","",6-Y11) -> 4 | AL11: =IF(COUNT(H11:O11)=8,SUM(H11:O11),"") -> 25 | AM11: =IF(COUNT(P11:U11,AH11:AK11)=10,SUM(P11:U11,AH11:AK11),"") | AN11: =IF(COUNT(Z11:AG11)=8,SUM(Z11:AG11),"") -> 25 | AO11: =IF(AL11="","",AL11/8) -> 3.125 | AP11: =IF(AM11="","",AM11/10) | AQ11: =IF(AN11="","",AN11/8) -> 3.125 | AR11: =IF(A11="","",IF(OR(F11=1,G11=1,AND(E11<>"",E11<=2)),2,IF(AND(E11>=3,G11=2,OR(F11=2,F11=3)),1,""))) -> 2 | AS11: =IF(AR11=1,"טיפוסי",IF(AR11=2,"מתקשה","")) -> מתקשה | AT11: =IF(AR11=1,AO11,"") | AU11: =IF(AR11=2,AO11,"") -> 3.125 | AV11: =IF(AR11=1,AP11,"") | AW11: =IF(AR11=2,AP11,"") | AX11: =IF(AR11=1,AQ11,"") | AY11: =IF(AR11=2,AQ11,"") -> 3.125
A12: 10 | B12: 1 | C12: 2 | D12: 13 | E12: 4 | F12: 2 | G12: 2 | H12: 4 | I12: 5 | J12: 5 | K12: 2 | L12: 5 | M12: 5 | N12: 5 | O12: 2 | P12: 3 | Q12: 5 | R12: 5 | S12: 4 | T12: 4 | U12: 4 | V12: 2 | W12: 1 | X12: 1 | Y12: 2 | Z12: 5 | AA12: 5 | AB12: 4 | AC12: 3 | AD12: 4 | AE12: 4 | AF12: 3 | AG12: 4 | AH12: =IF(V12="","",6-V12) -> 4 | AI12: =IF(W12="","",6-W12) -> 5 | AJ12: =IF(X12="","",6-X12) -> 5 | AK12: =IF(Y12="","",6-Y12) -> 4 | AL12: =IF(COUNT(H12:O12)=8,SUM(H12:O12),"") -> 33 | AM12: =IF(COUNT(P12:U12,AH12:AK12)=10,SUM(P12:U12,AH12:AK12),"") -> 43 | AN12: =IF(COUNT(Z12:AG12)=8,SUM(Z12:AG12),"") -> 32 | AO12: =IF(AL12="","",AL12/8) -> 4.125 | AP12: =IF(AM12="","",AM12/10) -> 4.3 | AQ12: =IF(AN12="","",AN12/8) -> 4 | AR12: =IF(A12="","",IF(OR(F12=1,G12=1,AND(E12<>"",E12<=2)),2,IF(AND(E12>=3,G12=2,OR(F12=2,F12=3)),1,""))) -> 1 | AS12: =IF(AR12=1,"טיפוסי",IF(AR12=2,"מתקשה","")) -> טיפוסי | AT12: =IF(AR12=1,AO12,"") -> 4.125 | AU12: =IF(AR12=2,AO12,"") | AV12: =IF(AR12=1,AP12,"") -> 4.3 | AW12: =IF(AR12=2,AP12,"") | AX12: =IF(AR12=1,AQ12,"") -> 4 | AY12: =IF(AR12=2,AQ12,"")
A13: 11 | B13: 1 | C13: 2 | D13: 14 | E13: 2 | F13: 2 | G13: 2 | H13: 3 | I13: 2 | J13: 3 | K13: 2 | L13: 4 | M13: 3 | N13: 5 | O13: 2 | P13: 4 | Q13: 3 | R13: 4 | S13: 3 | T13: 3 | U13: 2 | V13: 4 | W13: 3 | X13: 4 | Y13: 2 | Z13: 3 | AA13: 5 | AB13: 4 | AC13: 5 | AD13: 4 | AE13: 4 | AF13: 5 | AG13: 3 | AH13: =IF(V13="","",6-V13) -> 2 | AI13: =IF(W13="","",6-W13) -> 3 | AJ13: =IF(X13="","",6-X13) -> 2 | AK13: =IF(Y13="","",6-Y13) -> 4 | AL13: =IF(COUNT(H13:O13)=8,SUM(H13:O13),"") -> 24 | AM13: =IF(COUNT(P13:U13,AH13:AK13)=10,SUM(P13:U13,AH13:AK13),"") -> 30 | AN13: =IF(COUNT(Z13:AG13)=8,SUM(Z13:AG13),"") -> 33 | AO13: =IF(AL13="","",AL13/8) -> 3 | AP13: =IF(AM13="","",AM13/10) -> 3 | AQ13: =IF(AN13="","",AN13/8) -> 4.125 | AR13: =IF(A13="","",IF(OR(F13=1,G13=1,AND(E13<>"",E13<=2)),2,IF(AND(E13>=3,G13=2,OR(F13=2,F13=3)),1,""))) -> 2 | AS13: =IF(AR13=1,"טיפוסי",IF(AR13=2,"מתקשה","")) -> מתקשה | AT13: =IF(AR13=1,AO13,"") | AU13: =IF(AR13=2,AO13,"") -> 3 | AV13: =IF(AR13=1,AP13,"") | AW13: =IF(AR13=2,AP13,"") -> 3 | AX13: =IF(AR13=1,AQ13,"") | AY13: =IF(AR13=2,AQ13,"") -> 4.125
A14: 12 | B14: 1 | C14: 3 | D14: 15 | E14: 3 | F14: 2 | G14: 2 | H14: 5 | I14: 3 | J14: 4 | K14: 5 | L14: 4 | M14: 4 | N14: 5 | O14: 3 | P14: 3 | Q14: 4 | R14: 4 | S14: 3 | T14: 2 | U14: 4 | V14: 3 | W14: 4 | X14: 3 | Y14: 2 | Z14: 4 | AA14: 4 | AB14: 4 | AC14: 4 | AD14: 4 | AE14: 4 | AF14: 5 | AG14: 3 | AH14: =IF(V14="","",6-V14) -> 3 | AI14: =IF(W14="","",6-W14) -> 2 | AJ14: =IF(X14="","",6-X14) -> 3 | AK14: =IF(Y14="","",6-Y14) -> 4 | AL14: =IF(COUNT(H14:O14)=8,SUM(H14:O14),"") -> 33 | AM14: =IF(COUNT(P14:U14,AH14:AK14)=10,SUM(P14:U14,AH14:AK14),"") -> 32 | AN14: =IF(COUNT(Z14:AG14)=8,SUM(Z14:AG14),"") -> 32 | AO14: =IF(AL14="","",AL14/8) -> 4.125 | AP14: =IF(AM14="","",AM14/10) -> 3.2 | AQ14: =IF(AN14="","",AN14/8) -> 4 | AR14: =IF(A14="","",IF(OR(F14=1,G14=1,AND(E14<>"",E14<=2)),2,IF(AND(E14>=3,G14=2,OR(F14=2,F14=3)),1,""))) -> 1 | AS14: =IF(AR14=1,"טיפוסי",IF(AR14=2,"מתקשה","")) -> טיפוסי | AT14: =IF(AR14=1,AO14,"") -> 4.125 | AU14: =IF(AR14=2,AO14,"") | AV14: =IF(AR14=1,AP14,"") -> 3.2 | AW14: =IF(AR14=2,AP14,"") | AX14: =IF(AR14=1,AQ14,"") -> 4 | AY14: =IF(AR14=2,AQ14,"")
A15: 13 | B15: 2 | C15: 2 | D15: 13 | E15: 3 | F15: 1 | G15: 1 | H15: 4 | I15: 3 | J15: 4 | K15: 2 | L15: 4 | M15: 3 | N15: 3 | O15: 3 | P15: 4 | Q15: 5 | R15: 4 | S15: 5 | T15: 5 | U15: 5 | V15: 1 | W15: 1 | X15: 2 | Y15: 1 | Z15: 4 | AA15: 3 | AB15: 4 | AC15: 4 | AD15: 4 | AE15: 3 | AF15: 3 | AG15: 3 | AH15: =IF(V15="","",6-V15) -> 5 | AI15: =IF(W15="","",6-W15) -> 5 | AJ15: =IF(X15="","",6-X15) -> 4 | AK15: =IF(Y15="","",6-Y15) -> 5 | AL15: =IF(COUNT(H15:O15)=8,SUM(H15:O15),"") -> 26 | AM15: =IF(COUNT(P15:U15,AH15:AK15)=10,SUM(P15:U15,AH15:AK15),"") -> 47 | AN15: =IF(COUNT(Z15:AG15)=8,SUM(Z15:AG15),"") -> 28 | AO15: =IF(AL15="","",AL15/8) -> 3.25 | AP15: =IF(AM15="","",AM15/10) -> 4.7 | AQ15: =IF(AN15="","",AN15/8) -> 3.5 | AR15: =IF(A15="","",IF(OR(F15=1,G15=1,AND(E15<>"",E15<=2)),2,IF(AND(E15>=3,G15=2,OR(F15=2,F15=3)),1,""))) -> 2 | AS15: =IF(AR15=1,"טיפוסי",IF(AR15=2,"מתקשה","")) -> מתקשה | AT15: =IF(AR15=1,AO15,"") | AU15: =IF(AR15=2,AO15,"") -> 3.25 | AV15: =IF(AR15=1,AP15,"") | AW15: =IF(AR15=2,AP15,"") -> 4.7 | AX15: =IF(AR15=1,AQ15,"") | AY15: =IF(AR15=2,AQ15,"") -> 3.5
A16: 14 | B16: 1 | C16: 2 | D16: 14 | E16: 3 | F16: 2 | G16: 2 | H16: 2 | I16: 1 | J16: 3 | K16: 3 | L16: 1 | M16: 2 | N16: 4 | O16: 2 | P16: 2 | Q16: 3 | R16: 2 | S16: 4 | T16: 4 | U16: 2 | V16: 3 | W16: 3 | X16: 3 | Y16: 3 | Z16: 4 | AA16: 4 | AB16: 3 | AC16: 3 | AD16: 4 | AE16: 4 | AF16: 3 | AG16: 3 | AH16: =IF(V16="","",6-V16) -> 3 | AI16: =IF(W16="","",6-W16) -> 3 | AJ16: =IF(X16="","",6-X16) -> 3 | AK16: =IF(Y16="","",6-Y16) -> 3 | AL16: =IF(COUNT(H16:O16)=8,SUM(H16:O16),"") -> 18 | AM16: =IF(COUNT(P16:U16,AH16:AK16)=10,SUM(P16:U16,AH16:AK16),"") -> 29 | AN16: =IF(COUNT(Z16:AG16)=8,SUM(Z16:AG16),"") -> 28 | AO16: =IF(AL16="","",AL16/8) -> 2.25 | AP16: =IF(AM16="","",AM16/10) -> 2.9 | AQ16: =IF(AN16="","",AN16/8) -> 3.5 | AR16: =IF(A16="","",IF(OR(F16=1,G16=1,AND(E16<>"",E16<=2)),2,IF(AND(E16>=3,G16=2,OR(F16=2,F16=3)),1,""))) -> 1 | AS16: =IF(AR16=1,"טיפוסי",IF(AR16=2,"מתקשה","")) -> טיפוסי | AT16: =IF(AR16=1,AO16,"") -> 2.25 | AU16: =IF(AR16=2,AO16,"") | AV16: =IF(AR16=1,AP16,"") -> 2.9 | AW16: =IF(AR16=2,AP16,"") | AX16: =IF(AR16=1,AQ16,"") -> 3.5 | AY16: =IF(AR16=2,AQ16,"")
A17: 15 | B17: 1 | C17: 2 | D17: 13 | E17: 3 | F17: 2 | G17: 2 | H17: 2 | I17: 3 | J17: 1 | K17: 2 | L17: 3 | M17: 2 | N17: 2 | O17: 2 | P17: 3 | Q17: 2 | R17: 4 | S17: 2 | T17: 3 | U17: 4 | V17: 4 | W17: 5 | X17: 3 | Y17: 4 | Z17: 3 | AA17: 2 | AB17: 1 | AC17: 3 | AD17: 2 | AE17: 3 | AF17: 1 | AG17: 1 | AH17: =IF(V17="","",6-V17) -> 2 | AI17: =IF(W17="","",6-W17) -> 1 | AJ17: =IF(X17="","",6-X17) -> 3 | AK17: =IF(Y17="","",6-Y17) -> 2 | AL17: =IF(COUNT(H17:O17)=8,SUM(H17:O17),"") -> 17 | AM17: =IF(COUNT(P17:U17,AH17:AK17)=10,SUM(P17:U17,AH17:AK17),"") -> 26 | AN17: =IF(COUNT(Z17:AG17)=8,SUM(Z17:AG17),"") -> 16 | AO17: =IF(AL17="","",AL17/8) -> 2.125 | AP17: =IF(AM17="","",AM17/10) -> 2.6 | AQ17: =IF(AN17="","",AN17/8) -> 2 | AR17: =IF(A17="","",IF(OR(F17=1,G17=1,AND(E17<>"",E17<=2)),2,IF(AND(E17>=3,G17=2,OR(F17=2,F17=3)),1,""))) -> 1 | AS17: =IF(AR17=1,"טיפוסי",IF(AR17=2,"מתקשה","")) -> טיפוסי | AT17: =IF(AR17=1,AO17,"") -> 2.125 | AU17: =IF(AR17=2,AO17,"") | AV17: =IF(AR17=1,AP17,"") -> 2.6 | AW17: =IF(AR17=2,AP17,"") | AX17: =IF(AR17=1,AQ17,"") -> 2 | AY17: =IF(AR17=2,AQ17,"")
A18: 16 | B18: 2 | C18: 2 | D18: 14 | E18: 3 | F18: 2 | G18: 2 | H18: 5 | I18: 4 | J18: 3 | K18: 4 | L18: 5 | M18: 4 | N18: 4 | O18: 5 | P18: 5 | Q18: 4 | R18: 4 | S18: 5 | T18: 4 | U18: 4 | V18: 4 | W18: 2 | X18: 2 | Y18: 1 | Z18: 4 | AA18: 2 | AB18: 4 | AC18: 3 | AD18: 3 | AE18: 2 | AF18: 4 | AG18: 3 | AH18: =IF(V18="","",6-V18) -> 2 | AI18: =IF(W18="","",6-W18) -> 4 | AJ18: =IF(X18="","",6-X18) -> 4 | AK18: =IF(Y18="","",6-Y18) -> 5 | AL18: =IF(COUNT(H18:O18)=8,SUM(H18:O18),"") -> 34 | AM18: =IF(COUNT(P18:U18,AH18:AK18)=10,SUM(P18:U18,AH18:AK18),"") -> 41 | AN18: =IF(COUNT(Z18:AG18)=8,SUM(Z18:AG18),"") -> 25 | AO18: =IF(AL18="","",AL18/8) -> 4.25 | AP18: =IF(AM18="","",AM18/10) -> 4.1 | AQ18: =IF(AN18="","",AN18/8) -> 3.125 | AR18: =IF(A18="","",IF(OR(F18=1,G18=1,AND(E18<>"",E18<=2)),2,IF(AND(E18>=3,G18=2,OR(F18=2,F18=3)),1,""))) -> 1 | AS18: =IF(AR18=1,"טיפוסי",IF(AR18=2,"מתקשה","")) -> טיפוסי | AT18: =IF(AR18=1,AO18,"") -> 4.25 | AU18: =IF(AR18=2,AO18,"") | AV18: =IF(AR18=1,AP18,"") -> 4.1 | AW18: =IF(AR18=2,AP18,"") | AX18: =IF(AR18=1,AQ18,"") -> 3.125 | AY18: =IF(AR18=2,AQ18,"")
A19: 17 | B19: 1 | C19: 1 | D19: 12 | E19: 4 | F19: 2 | G19: 2 | H19: 3 | I19: 1 | J19: 3 | K19: 4 | L19: 2 | M19: 2 | N19: 1 | O19: 3 | P19: 5 | Q19: 3 | R19: 4 | S19: 5 | T19: 5 | U19: 5 | V19: 4 | W19: 3 | X19: 3 | Y19: 4 | Z19: 4 | AA19: 4 | AB19: 3 | AC19: 5 | AD19: 4 | AE19: 5 | AF19: 5 | AG19: 2 | AH19: =IF(V19="","",6-V19) -> 2 | AI19: =IF(W19="","",6-W19) -> 3 | AJ19: =IF(X19="","",6-X19) -> 3 | AK19: =IF(Y19="","",6-Y19) -> 2 | AL19: =IF(COUNT(H19:O19)=8,SUM(H19:O19),"") -> 19 | AM19: =IF(COUNT(P19:U19,AH19:AK19)=10,SUM(P19:U19,AH19:AK19),"") -> 37 | AN19: =IF(COUNT(Z19:AG19)=8,SUM(Z19:AG19),"") -> 32 | AO19: =IF(AL19="","",AL19/8) -> 2.375 | AP19: =IF(AM19="","",AM19/10) -> 3.7 | AQ19: =IF(AN19="","",AN19/8) -> 4 | AR19: =IF(A19="","",IF(OR(F19=1,G19=1,AND(E19<>"",E19<=2)),2,IF(AND(E19>=3,G19=2,OR(F19=2,F19=3)),1,""))) -> 1 | AS19: =IF(AR19=1,"טיפוסי",IF(AR19=2,"מתקשה","")) -> טיפוסי | AT19: =IF(AR19=1,AO19,"") -> 2.375 | AU19: =IF(AR19=2,AO19,"") | AV19: =IF(AR19=1,AP19,"") -> 3.7 | AW19: =IF(AR19=2,AP19,"") | AX19: =IF(AR19=1,AQ19,"") -> 4 | AY19: =IF(AR19=2,AQ19,"")
A20: 18 | B20: 2 | C20: 3 | D20: 14 | E20: 3 | F20: 2 | G20: 2 | H20: 4 | I20: 5 | J20: 4 | K20: 5 | L20: 5 | M20: 4 | N20: 4 | O20: 5 | P20: 5 | Q20: 5 | R20: 4 | S20: 5 | T20: 5 | U20: 4 | V20: 1 | W20: 2 | X20: 3 | Y20: 1 | Z20: 3 | AA20: 3 | AB20: 5 | AC20: 3 | AD20: 2 | AE20: 3 | AF20: 3 | AG20: 4 | AH20: =IF(V20="","",6-V20) -> 5 | AI20: =IF(W20="","",6-W20) -> 4 | AJ20: =IF(X20="","",6-X20) -> 3 | AK20: =IF(Y20="","",6-Y20) -> 5 | AL20: =IF(COUNT(H20:O20)=8,SUM(H20:O20),"") -> 36 | AM20: =IF(COUNT(P20:U20,AH20:AK20)=10,SUM(P20:U20,AH20:AK20),"") -> 45 | AN20: =IF(COUNT(Z20:AG20)=8,SUM(Z20:AG20),"") -> 26 | AO20: =IF(AL20="","",AL20/8) -> 4.5 | AP20: =IF(AM20="","",AM20/10) -> 4.5 | AQ20: =IF(AN20="","",AN20/8) -> 3.25 | AR20: =IF(A20="","",IF(OR(F20=1,G20=1,AND(E20<>"",E20<=2)),2,IF(AND(E20>=3,G20=2,OR(F20=2,F20=3)),1,""))) -> 1 | AS20: =IF(AR20=1,"טיפוסי",IF(AR20=2,"מתקשה","")) -> טיפוסי | AT20: =IF(AR20=1,AO20,"") -> 4.5 | AU20: =IF(AR20=2,AO20,"") | AV20: =IF(AR20=1,AP20,"") -> 4.5 | AW20: =IF(AR20=2,AP20,"") | AX20: =IF(AR20=1,AQ20,"") -> 3.25 | AY20: =IF(AR20=2,AQ20,"")
A21: 19 | B21: 2 | C21: 2 | D21: 13 | E21: 3 | F21: 2 | G21: 2 | H21: 4 | I21: 4 | J21: 4 | K21: 4 | L21: 5 | M21: 4 | N21: 4 | O21: 5 | P21: 4 | Q21: 4 | R21: 2 | S21: 3 | T21: 3 | U21: 4 | V21: 2 | W21: 2 | X21: 3 | Y21: 2 | Z21: 5 | AA21: 5 | AB21: 5 | AC21: 4 | AD21: 5 | AE21: 4 | AF21: 4 | AG21: 4 | AH21: =IF(V21="","",6-V21) -> 4 | AI21: =IF(W21="","",6-W21) -> 4 | AJ21: =IF(X21="","",6-X21) -> 3 | AK21: =IF(Y21="","",6-Y21) -> 4 | AL21: =IF(COUNT(H21:O21)=8,SUM(H21:O21),"") -> 34 | AM21: =IF(COUNT(P21:U21,AH21:AK21)=10,SUM(P21:U21,AH21:AK21),"") -> 35 | AN21: =IF(COUNT(Z21:AG21)=8,SUM(Z21:AG21),"") -> 36 | AO21: =IF(AL21="","",AL21/8) -> 4.25 | AP21: =IF(AM21="","",AM21/10) -> 3.5 | AQ21: =IF(AN21="","",AN21/8) -> 4.5 | AR21: =IF(A21="","",IF(OR(F21=1,G21=1,AND(E21<>"",E21<=2)),2,IF(AND(E21>=3,G21=2,OR(F21=2,F21=3)),1,""))) -> 1 | AS21: =IF(AR21=1,"טיפוסי",IF(AR21=2,"מתקשה","")) -> טיפוסי | AT21: =IF(AR21=1,AO21,"") -> 4.25 | AU21: =IF(AR21=2,AO21,"") | AV21: =IF(AR21=1,AP21,"") -> 3.5 | AW21: =IF(AR21=2,AP21,"") | AX21: =IF(AR21=1,AQ21,"") -> 4.5 | AY21: =IF(AR21=2,AQ21,"")
A22: 20 | B22: 1 | C22: 2 | D22: 13 | E22: 2 | F22: 1 | G22: 1 | H22: 4 | I22: 4 | J22: 3 | K22: 4 | L22: 4 | M22: 3 | N22: 4 | O22: 3 | P22: 1 | Q22: 3 | R22: 3 | S22: 3 | T22: 1 | U22: 2 | V22: 3 | W22: 5 | X22: 5 | Y22: 5 | Z22: 4 | AA22: 3 | AB22: 4 | AC22: 4 | AD22: 3 | AE22: 2 | AF22: 4 | AG22: 3 | AH22: =IF(V22="","",6-V22) -> 3 | AI22: =IF(W22="","",6-W22) -> 1 | AJ22: =IF(X22="","",6-X22) -> 1 | AK22: =IF(Y22="","",6-Y22) -> 1 | AL22: =IF(COUNT(H22:O22)=8,SUM(H22:O22),"") -> 29 | AM22: =IF(COUNT(P22:U22,AH22:AK22)=10,SUM(P22:U22,AH22:AK22),"") -> 19 | AN22: =IF(COUNT(Z22:AG22)=8,SUM(Z22:AG22),"") -> 27 | AO22: =IF(AL22="","",AL22/8) -> 3.625 | AP22: =IF(AM22="","",AM22/10) -> 1.9 | AQ22: =IF(AN22="","",AN22/8) -> 3.375 | AR22: =IF(A22="","",IF(OR(F22=1,G22=1,AND(E22<>"",E22<=2)),2,IF(AND(E22>=3,G22=2,OR(F22=2,F22=3)),1,""))) -> 2 | AS22: =IF(AR22=1,"טיפוסי",IF(AR22=2,"מתקשה","")) -> מתקשה | AT22: =IF(AR22=1,AO22,"") | AU22: =IF(AR22=2,AO22,"") -> 3.625 | AV22: =IF(AR22=1,AP22,"") | AW22: =IF(AR22=2,AP22,"") -> 1.9 | AX22: =IF(AR22=1,AQ22,"") | AY22: =IF(AR22=2,AQ22,"") -> 3.375
A23: 21 | B23: 2 | C23: 3 | D23: 15 | E23: 2 | F23: 1 | G23: 2 | H23: 5 | I23: 5 | J23: 5 | K23: 4 | L23: 5 | M23: 4 | N23: 4 | O23: 4 | P23: 4 | Q23: 2 | R23: 4 | S23: 3 | T23: 4 | U23: 2 | V23: 3 | W23: 4 | X23: 4 | Y23: 3 | Z23: 4 | AA23: 4 | AB23: 3 | AC23: 4 | AD23: 3 | AE23: 4 | AF23: 3 | AG23: 4 | AH23: =IF(V23="","",6-V23) -> 3 | AI23: =IF(W23="","",6-W23) -> 2 | AJ23: =IF(X23="","",6-X23) -> 2 | AK23: =IF(Y23="","",6-Y23) -> 3 | AL23: =IF(COUNT(H23:O23)=8,SUM(H23:O23),"") -> 36 | AM23: =IF(COUNT(P23:U23,AH23:AK23)=10,SUM(P23:U23,AH23:AK23),"") -> 29 | AN23: =IF(COUNT(Z23:AG23)=8,SUM(Z23:AG23),"") -> 29 | AO23: =IF(AL23="","",AL23/8) -> 4.5 | AP23: =IF(AM23="","",AM23/10) -> 2.9 | AQ23: =IF(AN23="","",AN23/8) -> 3.625 | AR23: =IF(A23="","",IF(OR(F23=1,G23=1,AND(E23<>"",E23<=2)),2,IF(AND(E23>=3,G23=2,OR(F23=2,F23=3)),1,""))) -> 2 | AS23: =IF(AR23=1,"טיפוסי",IF(AR23=2,"מתקשה","")) -> מתקשה | AT23: =IF(AR23=1,AO23,"") | AU23: =IF(AR23=2,AO23,"") -> 4.5 | AV23: =IF(AR23=1,AP23,"") | AW23: =IF(AR23=2,AP23,"") -> 2.9 | AX23: =IF(AR23=1,AQ23,"") | AY23: =IF(AR23=2,AQ23,"") -> 3.625
... A48: 46 | B48: 1 | C48: 2 | D48: 14 | E48: 3 | F48: 2 | G48: 2 | H48: 4 | I48: 3 | J48: 4 | K48: 3 | L48: 5 | M48: 4 | N48: 5 | O48: 4 | P48: 5 | Q48: 5 | R48: 5 | S48: 5 | T48: 5 | U48: 4 | V48: 1 | W48: 2 | X48: 3 | Y48: 1 | Z48: 4 | AA48: 4 | AB48: 5 | AC48: 4 | AD48: 5 | AE48: 5 | AF48: 5 | AG48: 5 | AH48: =IF(V48="","",6-V48) -> 5 | AI48: =IF(W48="","",6-W48) -> 4 | AJ48: =IF(X48="","",6-X48) -> 3 | AK48: =IF(Y48="","",6-Y48) -> 5 | AL48: =IF(COUNT(H48:O48)=8,SUM(H48:O48),"") -> 32 | AM48: =IF(COUNT(P48:U48,AH48:AK48)=10,SUM(P48:U48,AH48:AK48),"") -> 46 | AN48: =IF(COUNT(Z48:AG48)=8,SUM(Z48:AG48),"") -> 37 | AO48: =IF(AL48="","",AL48/8) -> 4 | AP48: =IF(AM48="","",AM48/10) -> 4.6 | AQ48: =IF(AN48="","",AN48/8) -> 4.625 | AR48: =IF(A48="","",IF(OR(F48=1,G48=1,AND(E48<>"",E48<=2)),2,IF(AND(E48>=3,G48=2,OR(F48=2,F48=3)),1,""))) -> 1 | AS48: =IF(AR48=1,"טיפוסי",IF(AR48=2,"מתקשה","")) -> טיפוסי | AT48: =IF(AR48=1,AO48,"") -> 4 | AU48: =IF(AR48=2,AO48,"") | AV48: =IF(AR48=1,AP48,"") -> 4.6 | AW48: =IF(AR48=2,AP48,"") | AX48: =IF(AR48=1,AQ48,"") -> 4.625 | AY48: =IF(AR48=2,AQ48,"")
A49: 47 | B49: 2 | C49: 1 | D49: 13 | E49: 2 | F49: 2 | G49: 2 | H49: 4 | I49: 5 | J49: 4 | K49: 5 | L49: 4 | M49: 5 | N49: 5 | O49: 3 | P49: 5 | Q49: 5 | R49: 5 | S49: 3 | T49: 5 | V49: 1 | W49: 2 | X49: 1 | Y49: 1 | Z49: 2 | AA49: 2 | AB49: 2 | AC49: 2 | AD49: 2 | AE49: 3 | AF49: 2 | AG49: 2 | AH49: =IF(V49="","",6-V49) -> 5 | AI49: =IF(W49="","",6-W49) -> 4 | AJ49: =IF(X49="","",6-X49) -> 5 | AK49: =IF(Y49="","",6-Y49) -> 5 | AL49: =IF(COUNT(H49:O49)=8,SUM(H49:O49),"") -> 35 | AM49: =IF(COUNT(P49:U49,AH49:AK49)=10,SUM(P49:U49,AH49:AK49),"") | AN49: =IF(COUNT(Z49:AG49)=8,SUM(Z49:AG49),"") -> 17 | AO49: =IF(AL49="","",AL49/8) -> 4.375 | AP49: =IF(AM49="","",AM49/10) | AQ49: =IF(AN49="","",AN49/8) -> 2.125 | AR49: =IF(A49="","",IF(OR(F49=1,G49=1,AND(E49<>"",E49<=2)),2,IF(AND(E49>=3,G49=2,OR(F49=2,F49=3)),1,""))) -> 2 | AS49: =IF(AR49=1,"טיפוסי",IF(AR49=2,"מתקשה","")) -> מתקשה | AT49: =IF(AR49=1,AO49,"") | AU49: =IF(AR49=2,AO49,"") -> 4.375 | AV49: =IF(AR49=1,AP49,"") | AW49: =IF(AR49=2,AP49,"") | AX49: =IF(AR49=1,AQ49,"") | AY49: =IF(AR49=2,AQ49,"") -> 2.125
A50: 48 | B50: 2 | C50: 1 | D50: 12 | E50: 3 | F50: 3 | G50: 2 | H50: 3 | I50: 3 | J50: 4 | K50: 3 | L50: 2 | M50: 4 | N50: 4 | O50: 3 | P50: 5 | Q50: 2 | R50: 4 | S50: 2 | T50: 4 | U50: 3 | V50: 3 | W50: 3 | X50: 4 | Y50: 3 | Z50: 3 | AA50: 4 | AB50: 3 | AC50: 2 | AD50: 2 | AE50: 2 | AF50: 2 | AG50: 4 | AH50: =IF(V50="","",6-V50) -> 3 | AI50: =IF(W50="","",6-W50) -> 3 | AJ50: =IF(X50="","",6-X50) -> 2 | AK50: =IF(Y50="","",6-Y50) -> 3 | AL50: =IF(COUNT(H50:O50)=8,SUM(H50:O50),"") -> 26 | AM50: =IF(COUNT(P50:U50,AH50:AK50)=10,SUM(P50:U50,AH50:AK50),"") -> 31 | AN50: =IF(COUNT(Z50:AG50)=8,SUM(Z50:AG50),"") -> 22 | AO50: =IF(AL50="","",AL50/8) -> 3.25 | AP50: =IF(AM50="","",AM50/10) -> 3.1 | AQ50: =IF(AN50="","",AN50/8) -> 2.75 | AR50: =IF(A50="","",IF(OR(F50=1,G50=1,AND(E50<>"",E50<=2)),2,IF(AND(E50>=3,G50=2,OR(F50=2,F50=3)),1,""))) -> 1 | AS50: =IF(AR50=1,"טיפוסי",IF(AR50=2,"מתקשה","")) -> טיפוסי | AT50: =IF(AR50=1,AO50,"") -> 3.25 | AU50: =IF(AR50=2,AO50,"") | AV50: =IF(AR50=1,AP50,"") -> 3.1 | AW50: =IF(AR50=2,AP50,"") | AX50: =IF(AR50=1,AQ50,"") -> 2.75 | AY50: =IF(AR50=2,AQ50,"")
A51: 49 | B51: 1 | C51: 2 | D51: 14 | E51: 2 | F51: 1 | G51: 1 | H51: 2 | I51: 1 | J51: 2 | K51: 4 | L51: 3 | M51: 1 | N51: 3 | O51: 2 | P51: 5 | Q51: 4 | R51: 2 | S51: 3 | T51: 4 | U51: 3 | V51: 3 | W51: 4 | X51: 3 | Y51: 2 | Z51: 2 | AA51: 3 | AB51: 3 | AC51: 3 | AD51: 5 | AE51: 2 | AF51: 4 | AG51: 3 | AH51: =IF(V51="","",6-V51) -> 3 | AI51: =IF(W51="","",6-W51) -> 2 | AJ51: =IF(X51="","",6-X51) -> 3 | AK51: =IF(Y51="","",6-Y51) -> 4 | AL51: =IF(COUNT(H51:O51)=8,SUM(H51:O51),"") -> 18 | AM51: =IF(COUNT(P51:U51,AH51:AK51)=10,SUM(P51:U51,AH51:AK51),"") -> 33 | AN51: =IF(COUNT(Z51:AG51)=8,SUM(Z51:AG51),"") -> 25 | AO51: =IF(AL51="","",AL51/8) -> 2.25 | AP51: =IF(AM51="","",AM51/10) -> 3.3 | AQ51: =IF(AN51="","",AN51/8) -> 3.125 | AR51: =IF(A51="","",IF(OR(F51=1,G51=1,AND(E51<>"",E51<=2)),2,IF(AND(E51>=3,G51=2,OR(F51=2,F51=3)),1,""))) -> 2 | AS51: =IF(AR51=1,"טיפוסי",IF(AR51=2,"מתקשה","")) -> מתקשה | AT51: =IF(AR51=1,AO51,"") | AU51: =IF(AR51=2,AO51,"") -> 2.25 | AV51: =IF(AR51=1,AP51,"") | AW51: =IF(AR51=2,AP51,"") -> 3.3 | AX51: =IF(AR51=1,AQ51,"") | AY51: =IF(AR51=2,AQ51,"") -> 3.125
A52: 50 | B52: 1 | C52: 1 | D52: 13 | E52: 4 | F52: 2 | G52: 2 | H52: 2 | I52: 1 | J52: 3 | K52: 3 | L52: 1 | M52: 4 | N52: 1 | O52: 2 | P52: 2 | Q52: 1 | R52: 1 | S52: 3 | T52: 2 | U52: 1 | V52: 4 | W52: 5 | X52: 4 | Y52: 5 | Z52: 3 | AA52: 2 | AB52: 2 | AC52: 3 | AD52: 4 | AE52: 3 | AF52: 2 | AG52: 2 | AH52: =IF(V52="","",6-V52) -> 2 | AI52: =IF(W52="","",6-W52) -> 1 | AJ52: =IF(X52="","",6-X52) -> 2 | AK52: =IF(Y52="","",6-Y52) -> 1 | AL52: =IF(COUNT(H52:O52)=8,SUM(H52:O52),"") -> 17 | AM52: =IF(COUNT(P52:U52,AH52:AK52)=10,SUM(P52:U52,AH52:AK52),"") -> 16 | AN52: =IF(COUNT(Z52:AG52)=8,SUM(Z52:AG52),"") -> 21 | AO52: =IF(AL52="","",AL52/8) -> 2.125 | AP52: =IF(AM52="","",AM52/10) -> 1.6 | AQ52: =IF(AN52="","",AN52/8) -> 2.625 | AR52: =IF(A52="","",IF(OR(F52=1,G52=1,AND(E52<>"",E52<=2)),2,IF(AND(E52>=3,G52=2,OR(F52=2,F52=3)),1,""))) -> 1 | AS52: =IF(AR52=1,"טיפוסי",IF(AR52=2,"מתקשה","")) -> טיפוסי | AT52: =IF(AR52=1,AO52,"") -> 2.125 | AU52: =IF(AR52=2,AO52,"") | AV52: =IF(AR52=1,AP52,"") -> 1.6 | AW52: =IF(AR52=2,AP52,"") | AX52: =IF(AR52=1,AQ52,"") -> 2.625 | AY52: =IF(AR52=2,AQ52,"")
A53: 51 | B53: 1 | C53: 3 | D53: 15 | E53: 3 | F53: 2 | G53: 2 | H53: 4 | I53: 5 | J53: 5 | K53: 5 | L53: 4 | M53: 5 | N53: 5 | O53: 5 | P53: 3 | Q53: 4 | R53: 2 | S53: 3 | T53: 3 | U53: 4 | V53: 5 | W53: 1 | X53: 2 | Y53: 2 | Z53: 3 | AA53: 3 | AB53: 3 | AC53: 3 | AD53: 3 | AE53: 4 | AF53: 3 | AG53: 5 | AH53: =IF(V53="","",6-V53) -> 1 | AI53: =IF(W53="","",6-W53) -> 5 | AJ53: =IF(X53="","",6-X53) -> 4 | AK53: =IF(Y53="","",6-Y53) -> 4 | AL53: =IF(COUNT(H53:O53)=8,SUM(H53:O53),"") -> 38 | AM53: =IF(COUNT(P53:U53,AH53:AK53)=10,SUM(P53:U53,AH53:AK53),"") -> 33 | AN53: =IF(COUNT(Z53:AG53)=8,SUM(Z53:AG53),"") -> 27 | AO53: =IF(AL53="","",AL53/8) -> 4.75 | AP53: =IF(AM53="","",AM53/10) -> 3.3 | AQ53: =IF(AN53="","",AN53/8) -> 3.375 | AR53: =IF(A53="","",IF(OR(F53=1,G53=1,AND(E53<>"",E53<=2)),2,IF(AND(E53>=3,G53=2,OR(F53=2,F53=3)),1,""))) -> 1 | AS53: =IF(AR53=1,"טיפוסי",IF(AR53=2,"מתקשה","")) -> טיפוסי | AT53: =IF(AR53=1,AO53,"") -> 4.75 | AU53: =IF(AR53=2,AO53,"") | AV53: =IF(AR53=1,AP53,"") -> 3.3 | AW53: =IF(AR53=2,AP53,"") | AX53: =IF(AR53=1,AQ53,"") -> 3.375 | AY53: =IF(AR53=2,AQ53,"")
A54: 52 | B54: 2 | C54: 2 | D54: 14 | E54: 3 | F54: 2 | G54: 2 | H54: 4 | I54: 4 | J54: 3 | K54: 2 | L54: 3 | M54: 5 | N54: 5 | O54: 5 | P54: 5 | Q54: 4 | R54: 3 | S54: 2 | T54: 3 | U54: 3 | V54: 5 | W54: 1 | X54: 3 | Y54: 3 | Z54: 4 | AA54: 4 | AB54: 4 | AC54: 3 | AD54: 5 | AE54: 4 | AF54: 5 | AG54: 3 | AH54: =IF(V54="","",6-V54) -> 1 | AI54: =IF(W54="","",6-W54) -> 5 | AJ54: =IF(X54="","",6-X54) -> 3 | AK54: =IF(Y54="","",6-Y54) -> 3 | AL54: =IF(COUNT(H54:O54)=8,SUM(H54:O54),"") -> 31 | AM54: =IF(COUNT(P54:U54,AH54:AK54)=10,SUM(P54:U54,AH54:AK54),"") -> 32 | AN54: =IF(COUNT(Z54:AG54)=8,SUM(Z54:AG54),"") -> 32 | AO54: =IF(AL54="","",AL54/8) -> 3.875 | AP54: =IF(AM54="","",AM54/10) -> 3.2 | AQ54: =IF(AN54="","",AN54/8) -> 4 | AR54: =IF(A54="","",IF(OR(F54=1,G54=1,AND(E54<>"",E54<=2)),2,IF(AND(E54>=3,G54=2,OR(F54=2,F54=3)),1,""))) -> 1 | AS54: =IF(AR54=1,"טיפוסי",IF(AR54=2,"מתקשה","")) -> טיפוסי | AT54: =IF(AR54=1,AO54,"") -> 3.875 | AU54: =IF(AR54=2,AO54,"") | AV54: =IF(AR54=1,AP54,"") -> 3.2 | AW54: =IF(AR54=2,AP54,"") | AX54: =IF(AR54=1,AQ54,"") -> 4 | AY54: =IF(AR54=2,AQ54,"")
A55: 53 | B55: 1 | C55: 3 | D55: 15 | E55: 3 | F55: 2 | G55: 2 | H55: 3 | I55: 4 | J55: 4 | K55: 1 | L55: 5 | M55: 5 | N55: 3 | O55: 2 | P55: 4 | Q55: 5 | R55: 3 | S55: 3 | T55: 4 | U55: 4 | V55: 3 | W55: 3 | X55: 3 | Y55: 2 | Z55: 3 | AA55: 2 | AB55: 4 | AC55: 5 | AD55: 4 | AE55: 4 | AF55: 4 | AG55: 4 | AH55: =IF(V55="","",6-V55) -> 3 | AI55: =IF(W55="","",6-W55) -> 3 | AJ55: =IF(X55="","",6-X55) -> 3 | AK55: =IF(Y55="","",6-Y55) -> 4 | AL55: =IF(COUNT(H55:O55)=8,SUM(H55:O55),"") -> 27 | AM55: =IF(COUNT(P55:U55,AH55:AK55)=10,SUM(P55:U55,AH55:AK55),"") -> 36 | AN55: =IF(COUNT(Z55:AG55)=8,SUM(Z55:AG55),"") -> 30 | AO55: =IF(AL55="","",AL55/8) -> 3.375 | AP55: =IF(AM55="","",AM55/10) -> 3.6 | AQ55: =IF(AN55="","",AN55/8) -> 3.75 | AR55: =IF(A55="","",IF(OR(F55=1,G55=1,AND(E55<>"",E55<=2)),2,IF(AND(E55>=3,G55=2,OR(F55=2,F55=3)),1,""))) -> 1 | AS55: =IF(AR55=1,"טיפוסי",IF(AR55=2,"מתקשה","")) -> טיפוסי | AT55: =IF(AR55=1,AO55,"") -> 3.375 | AU55: =IF(AR55=2,AO55,"") | AV55: =IF(AR55=1,AP55,"") -> 3.6 | AW55: =IF(AR55=2,AP55,"") | AX55: =IF(AR55=1,AQ55,"") -> 3.75 | AY55: =IF(AR55=2,AQ55,"")
A56: 54 | B56: 1 | C56: 2 | D56: 14 | E56: 2 | F56: 3 | G56: 1 | H56: 3 | I56: 4 | J56: 4 | K56: 5 | L56: 3 | M56: 3 | N56: 5 | O56: 5 | P56: 3 | Q56: 4 | R56: 3 | S56: 2 | T56: 3 | U56: 4 | V56: 4 | W56: 3 | X56: 5 | Y56: 3 | Z56: 2 | AA56: 4 | AB56: 4 | AC56: 4 | AD56: 3 | AE56: 4 | AF56: 4 | AG56: 2 | AH56: =IF(V56="","",6-V56) -> 2 | AI56: =IF(W56="","",6-W56) -> 3 | AJ56: =IF(X56="","",6-X56) -> 1 | AK56: =IF(Y56="","",6-Y56) -> 3 | AL56: =IF(COUNT(H56:O56)=8,SUM(H56:O56),"") -> 32 | AM56: =IF(COUNT(P56:U56,AH56:AK56)=10,SUM(P56:U56,AH56:AK56),"") -> 28 | AN56: =IF(COUNT(Z56:AG56)=8,SUM(Z56:AG56),"") -> 27 | AO56: =IF(AL56="","",AL56/8) -> 4 | AP56: =IF(AM56="","",AM56/10) -> 2.8 | AQ56: =IF(AN56="","",AN56/8) -> 3.375 | AR56: =IF(A56="","",IF(OR(F56=1,G56=1,AND(E56<>"",E56<=2)),2,IF(AND(E56>=3,G56=2,OR(F56=2,F56=3)),1,""))) -> 2 | AS56: =IF(AR56=1,"טיפוסי",IF(AR56=2,"מתקשה","")) -> מתקשה | AT56: =IF(AR56=1,AO56,"") | AU56: =IF(AR56=2,AO56,"") -> 4 | AV56: =IF(AR56=1,AP56,"") | AW56: =IF(AR56=2,AP56,"") -> 2.8 | AX56: =IF(AR56=1,AQ56,"") | AY56: =IF(AR56=2,AQ56,"") -> 3.375
A57: 55 | B57: 2 | C57: 1 | D57: 13 | E57: 3 | F57: 2 | G57: 2 | H57: 4 | I57: 3 | J57: 4 | K57: 4 | L57: 3 | M57: 3 | N57: 3 | O57: 3 | P57: 2 | Q57: 2 | R57: 3 | S57: 2 | T57: 3 | U57: 3 | V57: 5 | W57: 5 | X57: 5 | Y57: 4 | Z57: 3 | AA57: 3 | AB57: 3 | AC57: 4 | AD57: 4 | AE57: 3 | AF57: 4 | AG57: 2 | AH57: =IF(V57="","",6-V57) -> 1 | AI57: =IF(W57="","",6-W57) -> 1 | AJ57: =IF(X57="","",6-X57) -> 1 | AK57: =IF(Y57="","",6-Y57) -> 2 | AL57: =IF(COUNT(H57:O57)=8,SUM(H57:O57),"") -> 27 | AM57: =IF(COUNT(P57:U57,AH57:AK57)=10,SUM(P57:U57,AH57:AK57),"") -> 20 | AN57: =IF(COUNT(Z57:AG57)=8,SUM(Z57:AG57),"") -> 26 | AO57: =IF(AL57="","",AL57/8) -> 3.375 | AP57: =IF(AM57="","",AM57/10) -> 2 | AQ57: =IF(AN57="","",AN57/8) -> 3.25 | AR57: =IF(A57="","",IF(OR(F57=1,G57=1,AND(E57<>"",E57<=2)),2,IF(AND(E57>=3,G57=2,OR(F57=2,F57=3)),1,""))) -> 1 | AS57: =IF(AR57=1,"טיפוסי",IF(AR57=2,"מתקשה","")) -> טיפוסי | AT57: =IF(AR57=1,AO57,"") -> 3.375 | AU57: =IF(AR57=2,AO57,"") | AV57: =IF(AR57=1,AP57,"") -> 2 | AW57: =IF(AR57=2,AP57,"") | AX57: =IF(AR57=1,AQ57,"") -> 3.25 | AY57: =IF(AR57=2,AQ57,"")
A58: 56 | B58: 1 | C58: 1 | D58: 13 | E58: 3 | F58: 2 | G58: 2 | H58: 3 | I58: 3 | J58: 2 | K58: 5 | L58: 2 | M58: 3 | N58: 2 | O58: 4 | P58: 5 | Q58: 5 | R58: 5 | S58: 4 | T58: 2 | U58: 3 | V58: 1 | W58: 1 | X58: 1 | Y58: 2 | Z58: 5 | AA58: 5 | AB58: 4 | AC58: 4 | AD58: 3 | AE58: 4 | AF58: 5 | AG58: 4 | AH58: =IF(V58="","",6-V58) -> 5 | AI58: =IF(W58="","",6-W58) -> 5 | AJ58: =IF(X58="","",6-X58) -> 5 | AK58: =IF(Y58="","",6-Y58) -> 4 | AL58: =IF(COUNT(H58:O58)=8,SUM(H58:O58),"") -> 24 | AM58: =IF(COUNT(P58:U58,AH58:AK58)=10,SUM(P58:U58,AH58:AK58),"") -> 43 | AN58: =IF(COUNT(Z58:AG58)=8,SUM(Z58:AG58),"") -> 34 | AO58: =IF(AL58="","",AL58/8) -> 3 | AP58: =IF(AM58="","",AM58/10) -> 4.3 | AQ58: =IF(AN58="","",AN58/8) -> 4.25 | AR58: =IF(A58="","",IF(OR(F58=1,G58=1,AND(E58<>"",E58<=2)),2,IF(AND(E58>=3,G58=2,OR(F58=2,F58=3)),1,""))) -> 1 | AS58: =IF(AR58=1,"טיפוסי",IF(AR58=2,"מתקשה","")) -> טיפוסי | AT58: =IF(AR58=1,AO58,"") -> 3 | AU58: =IF(AR58=2,AO58,"") | AV58: =IF(AR58=1,AP58,"") -> 4.3 | AW58: =IF(AR58=2,AP58,"") | AX58: =IF(AR58=1,AQ58,"") -> 4.25 | AY58: =IF(AR58=2,AQ58,"")
A59: 57 | B59: 1 | C59: 3 | D59: 15 | E59: 3 | F59: 2 | G59: 2 | H59: 2 | I59: 4 | J59: 4 | K59: 3 | L59: 2 | M59: 4 | N59: 3 | O59: 5 | P59: 4 | Q59: 2 | R59: 3 | S59: 2 | T59: 3 | U59: 2 | V59: 2 | W59: 5 | X59: 2 | Y59: 4 | Z59: 4 | AA59: 3 | AB59: 3 | AC59: 4 | AD59: 2 | AE59: 3 | AF59: 3 | AG59: 3 | AH59: =IF(V59="","",6-V59) -> 4 | AI59: =IF(W59="","",6-W59) -> 1 | AJ59: =IF(X59="","",6-X59) -> 4 | AK59: =IF(Y59="","",6-Y59) -> 2 | AL59: =IF(COUNT(H59:O59)=8,SUM(H59:O59),"") -> 27 | AM59: =IF(COUNT(P59:U59,AH59:AK59)=10,SUM(P59:U59,AH59:AK59),"") -> 27 | AN59: =IF(COUNT(Z59:AG59)=8,SUM(Z59:AG59),"") -> 25 | AO59: =IF(AL59="","",AL59/8) -> 3.375 | AP59: =IF(AM59="","",AM59/10) -> 2.7 | AQ59: =IF(AN59="","",AN59/8) -> 3.125 | AR59: =IF(A59="","",IF(OR(F59=1,G59=1,AND(E59<>"",E59<=2)),2,IF(AND(E59>=3,G59=2,OR(F59=2,F59=3)),1,""))) -> 1 | AS59: =IF(AR59=1,"טיפוסי",IF(AR59=2,"מתקשה","")) -> טיפוסי | AT59: =IF(AR59=1,AO59,"") -> 3.375 | AU59: =IF(AR59=2,AO59,"") | AV59: =IF(AR59=1,AP59,"") -> 2.7 | AW59: =IF(AR59=2,AP59,"") | AX59: =IF(AR59=1,AQ59,"") -> 3.125 | AY59: =IF(AR59=2,AQ59,"")
A60: 58 | B60: 2 | C60: 1 | D60: 12 | E60: 3 | F60: 2 | G60: 2 | H60: 3 | I60: 5 | J60: 3 | K60: 5 | L60: 3 | M60: 5 | N60: 4 | O60: 3 | P60: 4 | Q60: 4 | R60: 3 | S60: 3 | T60: 3 | U60: 3 | V60: 3 | W60: 3 | X60: 3 | Y60: 4 | Z60: 5 | AA60: 3 | AB60: 2 | AC60: 4 | AD60: 4 | AE60: 4 | AF60: 4 | AG60: 3 | AH60: =IF(V60="","",6-V60) -> 3 | AI60: =IF(W60="","",6-W60) -> 3 | AJ60: =IF(X60="","",6-X60) -> 3 | AK60: =IF(Y60="","",6-Y60) -> 2 | AL60: =IF(COUNT(H60:O60)=8,SUM(H60:O60),"") -> 31 | AM60: =IF(COUNT(P60:U60,AH60:AK60)=10,SUM(P60:U60,AH60:AK60),"") -> 31 | AN60: =IF(COUNT(Z60:AG60)=8,SUM(Z60:AG60),"") -> 29 | AO60: =IF(AL60="","",AL60/8) -> 3.875 | AP60: =IF(AM60="","",AM60/10) -> 3.1 | AQ60: =IF(AN60="","",AN60/8) -> 3.625 | AR60: =IF(A60="","",IF(OR(F60=1,G60=1,AND(E60<>"",E60<=2)),2,IF(AND(E60>=3,G60=2,OR(F60=2,F60=3)),1,""))) -> 1 | AS60: =IF(AR60=1,"טיפוסי",IF(AR60=2,"מתקשה","")) -> טיפוסי | AT60: =IF(AR60=1,AO60,"") -> 3.875 | AU60: =IF(AR60=2,AO60,"") | AV60: =IF(AR60=1,AP60,"") -> 3.1 | AW60: =IF(AR60=2,AP60,"") | AX60: =IF(AR60=1,AQ60,"") -> 3.625 | AY60: =IF(AR60=2,AQ60,"")
A61: 59 | B61: 2 | C61: 3 | D61: 15 | E61: 3 | F61: 2 | G61: 2 | H61: 4 | I61: 3 | J61: 4 | K61: 4 | L61: 1 | M61: 4 | N61: 2 | O61: 4 | P61: 4 | Q61: 4 | R61: 5 | S61: 5 | T61: 4 | U61: 5 | V61: 2 | W61: 3 | X61: 3 | Y61: 3 | Z61: 5 | AA61: 4 | AB61: 4 | AC61: 5 | AD61: 5 | AE61: 3 | AF61: 4 | AG61: 5 | AH61: =IF(V61="","",6-V61) -> 4 | AI61: =IF(W61="","",6-W61) -> 3 | AJ61: =IF(X61="","",6-X61) -> 3 | AK61: =IF(Y61="","",6-Y61) -> 3 | AL61: =IF(COUNT(H61:O61)=8,SUM(H61:O61),"") -> 26 | AM61: =IF(COUNT(P61:U61,AH61:AK61)=10,SUM(P61:U61,AH61:AK61),"") -> 40 | AN61: =IF(COUNT(Z61:AG61)=8,SUM(Z61:AG61),"") -> 35 | AO61: =IF(AL61="","",AL61/8) -> 3.25 | AP61: =IF(AM61="","",AM61/10) -> 4 | AQ61: =IF(AN61="","",AN61/8) -> 4.375 | AR61: =IF(A61="","",IF(OR(F61=1,G61=1,AND(E61<>"",E61<=2)),2,IF(AND(E61>=3,G61=2,OR(F61=2,F61=3)),1,""))) -> 1 | AS61: =IF(AR61=1,"טיפוסי",IF(AR61=2,"מתקשה","")) -> טיפוסי | AT61: =IF(AR61=1,AO61,"") -> 3.25 | AU61: =IF(AR61=2,AO61,"") | AV61: =IF(AR61=1,AP61,"") -> 4 | AW61: =IF(AR61=2,AP61,"") | AX61: =IF(AR61=1,AQ61,"") -> 4.375 | AY61: =IF(AR61=2,AQ61,"")
... A81: 79 | B81: 2 | C81: 2 | D81: 13 | E81: 2 | F81: 3 | G81: 2 | H81: 4 | I81: 4 | J81: 2 | K81: 1 | L81: 1 | M81: 2 | N81: 1 | O81: 2 | P81: 2 | Q81: 3 | R81: 1 | S81: 2 | T81: 3 | U81: 1 | V81: 3 | W81: 4 | X81: 2 | Y81: 2 | Z81: 3 | AA81: 4 | AB81: 3 | AC81: 5 | AD81: 5 | AE81: 3 | AF81: 2 | AG81: 3 | AH81: =IF(V81="","",6-V81) -> 3 | AI81: =IF(W81="","",6-W81) -> 2 | AJ81: =IF(X81="","",6-X81) -> 4 | AK81: =IF(Y81="","",6-Y81) -> 4 | AL81: =IF(COUNT(H81:O81)=8,SUM(H81:O81),"") -> 17 | AM81: =IF(COUNT(P81:U81,AH81:AK81)=10,SUM(P81:U81,AH81:AK81),"") -> 25 | AN81: =IF(COUNT(Z81:AG81)=8,SUM(Z81:AG81),"") -> 28 | AO81: =IF(AL81="","",AL81/8) -> 2.125 | AP81: =IF(AM81="","",AM81/10) -> 2.5 | AQ81: =IF(AN81="","",AN81/8) -> 3.5 | AR81: =IF(A81="","",IF(OR(F81=1,G81=1,AND(E81<>"",E81<=2)),2,IF(AND(E81>=3,G81=2,OR(F81=2,F81=3)),1,""))) -> 2 | AS81: =IF(AR81=1,"טיפוסי",IF(AR81=2,"מתקשה","")) -> מתקשה | AT81: =IF(AR81=1,AO81,"") | AU81: =IF(AR81=2,AO81,"") -> 2.125 | AV81: =IF(AR81=1,AP81,"") | AW81: =IF(AR81=2,AP81,"") -> 2.5 | AX81: =IF(AR81=1,AQ81,"") | AY81: =IF(AR81=2,AQ81,"") -> 3.5
A82: 80 | B82: 1 | C82: 1 | D82: 12 | E82: 3 | F82: 2 | G82: 2 | H82: 5 | I82: 4 | J82: 5 | K82: 4 | L82: 5 | M82: 5 | N82: 4 | O82: 4 | P82: 4 | Q82: 3 | R82: 4 | S82: 3 | U82: 4 | V82: 3 | W82: 2 | X82: 3 | Y82: 3 | Z82: 4 | AA82: 3 | AB82: 4 | AC82: 4 | AD82: 4 | AE82: 4 | AF82: 3 | AG82: 4 | AH82: =IF(V82="","",6-V82) -> 3 | AI82: =IF(W82="","",6-W82) -> 4 | AJ82: =IF(X82="","",6-X82) -> 3 | AK82: =IF(Y82="","",6-Y82) -> 3 | AL82: =IF(COUNT(H82:O82)=8,SUM(H82:O82),"") -> 36 | AM82: =IF(COUNT(P82:U82,AH82:AK82)=10,SUM(P82:U82,AH82:AK82),"") | AN82: =IF(COUNT(Z82:AG82)=8,SUM(Z82:AG82),"") -> 30 | AO82: =IF(AL82="","",AL82/8) -> 4.5 | AP82: =IF(AM82="","",AM82/10) | AQ82: =IF(AN82="","",AN82/8) -> 3.75 | AR82: =IF(A82="","",IF(OR(F82=1,G82=1,AND(E82<>"",E82<=2)),2,IF(AND(E82>=3,G82=2,OR(F82=2,F82=3)),1,""))) -> 1 | AS82: =IF(AR82=1,"טיפוסי",IF(AR82=2,"מתקשה","")) -> טיפוסי | AT82: =IF(AR82=1,AO82,"") -> 4.5 | AU82: =IF(AR82=2,AO82,"") | AV82: =IF(AR82=1,AP82,"") | AW82: =IF(AR82=2,AP82,"") | AX82: =IF(AR82=1,AQ82,"") -> 3.75 | AY82: =IF(AR82=2,AQ82,"")
A83: 81 | B83: 1 | C83: 3 | D83: 14 | E83: 3 | F83: 2 | G83: 2 | H83: 4 | I83: 5 | J83: 3 | K83: 4 | L83: 3 | M83: 4 | N83: 3 | O83: 3 | P83: 2 | Q83: 2 | R83: 3 | S83: 4 | T83: 4 | U83: 3 | V83: 4 | W83: 3 | X83: 5 | Y83: 4 | Z83: 3 | AA83: 3 | AB83: 4 | AC83: 2 | AD83: 3 | AE83: 3 | AF83: 4 | AG83: 3 | AH83: =IF(V83="","",6-V83) -> 2 | AI83: =IF(W83="","",6-W83) -> 3 | AJ83: =IF(X83="","",6-X83) -> 1 | AK83: =IF(Y83="","",6-Y83) -> 2 | AL83: =IF(COUNT(H83:O83)=8,SUM(H83:O83),"") -> 29 | AM83: =IF(COUNT(P83:U83,AH83:AK83)=10,SUM(P83:U83,AH83:AK83),"") -> 26 | AN83: =IF(COUNT(Z83:AG83)=8,SUM(Z83:AG83),"") -> 25 | AO83: =IF(AL83="","",AL83/8) -> 3.625 | AP83: =IF(AM83="","",AM83/10) -> 2.6 | AQ83: =IF(AN83="","",AN83/8) -> 3.125 | AR83: =IF(A83="","",IF(OR(F83=1,G83=1,AND(E83<>"",E83<=2)),2,IF(AND(E83>=3,G83=2,OR(F83=2,F83=3)),1,""))) -> 1 | AS83: =IF(AR83=1,"טיפוסי",IF(AR83=2,"מתקשה","")) -> טיפוסי | AT83: =IF(AR83=1,AO83,"") -> 3.625 | AU83: =IF(AR83=2,AO83,"") | AV83: =IF(AR83=1,AP83,"") -> 2.6 | AW83: =IF(AR83=2,AP83,"") | AX83: =IF(AR83=1,AQ83,"") -> 3.125 | AY83: =IF(AR83=2,AQ83,"")
...

Sheet תיאורי
A1: סטטיסטיקה תיאורית
A2: מתעדכן אוטומטית מגיליון 'נתונים'. ממוצעים בסולם 1–5.
A4: משתנה | B4: N | C4: ממוצע | D4: סטיית תקן | E4: מינימום | F4: מקסימום
A5: יצירתיות | B5: =COUNT(נתונים!$AO$3:$AO$302) -> 102 | C5: =IFERROR(AVERAGE(נתונים!$AO$3:$AO$302),"") -> 3.5232843 | D5: =IFERROR(STDEV(נתונים!$AO$3:$AO$302),"") -> 0.73367767 | E5: =IF(B5=0,"",MIN(נתונים!$AO$3:$AO$302)) -> 1.875 | F5: =IF(B5=0,"",MAX(נתונים!$AO$3:$AO$302)) -> 5
A6: קבלת החלטות בפתרון בעיות | B6: =COUNT(נתונים!$AP$3:$AP$302) -> 99 | C6: =IFERROR(AVERAGE(נתונים!$AP$3:$AP$302),"") -> 3.1868687 | D6: =IFERROR(STDEV(נתונים!$AP$3:$AP$302),"") -> 0.77468183 | E6: =IF(B6=0,"",MIN(נתונים!$AP$3:$AP$302)) -> 1.5 | F6: =IF(B6=0,"",MAX(נתונים!$AP$3:$AP$302)) -> 4.7
A7: הנאה מלמידה | B7: =COUNT(נתונים!$AQ$3:$AQ$302) -> 101 | C7: =IFERROR(AVERAGE(נתונים!$AQ$3:$AQ$302),"") -> 3.5136139 | D7: =IFERROR(STDEV(נתונים!$AQ$3:$AQ$302),"") -> 0.67149576 | E7: =IF(B7=0,"",MIN(נתונים!$AQ$3:$AQ$302)) -> 1.875 | F7: =IF(B7=0,"",MAX(נתונים!$AQ$3:$AQ$302)) -> 5
A9: לפי קבוצה
B10: תלמידים טיפוסיים | E10: תלמידים מתקשים
A11: משתנה | B11: N | C11: ממוצע | D11: סטיית תקן | E11: N | F11: ממוצע | G11: סטיית תקן
A12: יצירתיות | B12: =COUNT(נתונים!$AT$3:$AT$302) -> 72 | C12: =IFERROR(AVERAGE(נתונים!$AT$3:$AT$302),"") -> 3.609375 | D12: =IFERROR(STDEV(נתונים!$AT$3:$AT$302),"") -> 0.69515979 | E12: =COUNT(נתונים!$AU$3:$AU$302) -> 30 | F12: =IFERROR(AVERAGE(נתונים!$AU$3:$AU$302),"") -> 3.3166667 | G12: =IFERROR(STDEV(נתונים!$AU$3:$AU$302),"") -> 0.7931097
A13: קבלת החלטות בפתרון בעיות | B13: =COUNT(נתונים!$AV$3:$AV$302) -> 71 | C13: =IFERROR(AVERAGE(נתונים!$AV$3:$AV$302),"") -> 3.2549296 | D13: =IFERROR(STDEV(נתונים!$AV$3:$AV$302),"") -> 0.74484682 | E13: =COUNT(נתונים!$AW$3:$AW$302) -> 28 | F13: =IFERROR(AVERAGE(נתונים!$AW$3:$AW$302),"") -> 3.0142857 | G13: =IFERROR(STDEV(נתונים!$AW$3:$AW$302),"") -> 0.83476068
A14: הנאה מלמידה | B14: =COUNT(נתונים!$AX$3:$AX$302) -> 71 | C14: =IFERROR(AVERAGE(נתונים!$AX$3:$AX$302),"") -> 3.6390845 | D14: =IFERROR(STDEV(נתונים!$AX$3:$AX$302),"") -> 0.68123748 | E14: =COUNT(נתונים!$AY$3:$AY$302) -> 30 | F14: =IFERROR(AVERAGE(נתונים!$AY$3:$AY$302),"") -> 3.2166667 | G14: =IFERROR(STDEV(נתונים!$AY$3:$AY$302),"") -> 0.55216398
A16: מאפייני המדגם
A17: משתנה / קטגוריה | B17: n | C17: %
A18: סה"כ שאלונים | B18: =COUNT(נתונים!$A$3:$A$302) -> 102
A19: מגדר
A20: בן | B20: =COUNTIF(נתונים!$B$3:$B$302,1) -> 51 | C20: =IF($B$18=0,"",B20/$B$18) -> 0.5
A21: בת | B21: =COUNTIF(נתונים!$B$3:$B$302,2) -> 51 | C21: =IF($B$18=0,"",B21/$B$18) -> 0.5
A22: כיתה
A23: ז' | B23: =COUNTIF(נתונים!$C$3:$C$302,1) -> 35 | C23: =IF($B$18=0,"",B23/$B$18) -> 0.34313725
A24: ח' | B24: =COUNTIF(נתונים!$C$3:$C$302,2) -> 34 | C24: =IF($B$18=0,"",B24/$B$18) -> 0.33333333
A25: ט' | B25: =COUNTIF(נתונים!$C$3:$C$302,3) -> 33 | C25: =IF($B$18=0,"",B25/$B$18) -> 0.32352941
A26: ציון אחרון במדעים
A27: מתחת ל-55 | B27: =COUNTIF(נתונים!$E$3:$E$302,1) -> 4 | C27: =IF($B$18=0,"",B27/$B$18) -> 0.039215686
A28: 55–69 | B28: =COUNTIF(נתונים!$E$3:$E$302,2) -> 16 | C28: =IF($B$18=0,"",B28/$B$18) -> 0.15686275
A29: 70–84 | B29: =COUNTIF(נתונים!$E$3:$E$302,3) -> 58 | C29: =IF($B$18=0,"",B29/$B$18) -> 0.56862745
A30: 85–100 | B30: =COUNTIF(נתונים!$E$3:$E$302,4) -> 24 | C30: =IF($B$18=0,"",B30/$B$18) -> 0.23529412
A31: אבחון לקות למידה / קשב
A32: כן | B32: =COUNTIF(נתונים!$F$3:$F$302,1) -> 14 | C32: =IF($B$18=0,"",B32/$B$18) -> 0.1372549
A33: לא | B33: =COUNTIF(נתונים!$F$3:$F$302,2) -> 72 | C33: =IF($B$18=0,"",B33/$B$18) -> 0.70588235
A34: לא יודע/ת | B34: =COUNTIF(נתונים!$F$3:$F$302,3) -> 16 | C34: =IF($B$18=0,"",B34/$B$18) -> 0.15686275
A35: שעות תמיכה / שילוב
A36: כן | B36: =COUNTIF(נתונים!$G$3:$G$302,1) -> 13 | C36: =IF($B$18=0,"",B36/$B$18) -> 0.12745098
A37: לא | B37: =COUNTIF(נתונים!$G$3:$G$302,2) -> 89 | C37: =IF($B$18=0,"",B37/$B$18) -> 0.87254902
A38: קבוצה
A39: טיפוסי | B39: =COUNTIF(נתונים!$AR$3:$AR$302,1) -> 72 | C39: =IF($B$18=0,"",B39/$B$18) -> 0.70588235
A40: מתקשה | B40: =COUNTIF(נתונים!$AR$3:$AR$302,2) -> 30 | C40: =IF($B$18=0,"",B40/$B$18) -> 0.29411765
A41: גיל: ממוצע (סטיית תקן) | B41: =IFERROR(AVERAGE(נתונים!$D$3:$D$302),"") -> 13.558824 | C41: =IFERROR(STDEV(נתונים!$D$3:$D$302),"") -> 0.9603375

Sheet מתאמים
A1: מתאמי פירסון בין המשתנים (שאלת המחקר)
A2: r = מתאם פירסון; p דו-צדדי; * p<.05 ** p<.01 *** p<.001
B4: כל המדגם | F4: תלמידים טיפוסיים | J4: תלמידים מתקשים
A5: זוג משתנים | B5: r | C5: n | D5: p | E5: מובהקות | F5: r | G5: n | H5: p | I5: מובהקות | J5: r | K5: n | L5: p | M5: מובהקות
A6: יצירתיות × קבלת החלטות | B6: =IFERROR(CORREL(נתונים!$AO$3:$AO$302,נתונים!$AP$3:$AP$302),"") -> 0.32794029 | C6: =SUMPRODUCT(ISNUMBER(נתונים!$AO$3:$AO$302)*ISNUMBER(נתונים!$AP$3:$AP$302)) -> 99 | D6: =IFERROR(TDIST(ABS(B6)*SQRT((C6-2)/(1-B6^2)),C6-2,2),"") -> 0.00092082544 | E6: =IF(D6="","",IF(D6<0.001,"***",IF(D6<0.01,"**",IF(D6<0.05,"*","n.s.")))) -> *** | F6: =IFERROR(CORREL(נתונים!$AT$3:$AT$302,נתונים!$AV$3:$AV$302),"") -> 0.19467255 | G6: =SUMPRODUCT(ISNUMBER(נתונים!$AT$3:$AT$302)*ISNUMBER(נתונים!$AV$3:$AV$302)) -> 71 | H6: =IFERROR(TDIST(ABS(F6)*SQRT((G6-2)/(1-F6^2)),G6-2,2),"") -> 0.10377332 | I6: =IF(H6="","",IF(H6<0.001,"***",IF(H6<0.01,"**",IF(H6<0.05,"*","n.s.")))) -> n.s. | J6: =IFERROR(CORREL(נתונים!$AU$3:$AU$302,נתונים!$AW$3:$AW$302),"") -> 0.54135655 | K6: =SUMPRODUCT(ISNUMBER(נתונים!$AU$3:$AU$302)*ISNUMBER(נתונים!$AW$3:$AW$302)) -> 28 | L6: =IFERROR(TDIST(ABS(J6)*SQRT((K6-2)/(1-J6^2)),K6-2,2),"") -> 0.0029299425 | M6: =IF(L6="","",IF(L6<0.001,"***",IF(L6<0.01,"**",IF(L6<0.05,"*","n.s.")))) -> **
A7: יצירתיות × הנאה מלמידה | B7: =IFERROR(CORREL(נתונים!$AO$3:$AO$302,נתונים!$AQ$3:$AQ$302),"") -> 0.31748303 | C7: =SUMPRODUCT(ISNUMBER(נתונים!$AO$3:$AO$302)*ISNUMBER(נתונים!$AQ$3:$AQ$302)) -> 101 | D7: =IFERROR(TDIST(ABS(B7)*SQRT((C7-2)/(1-B7^2)),C7-2,2),"") -> 0.0012161051 | E7: =IF(D7="","",IF(D7<0.001,"***",IF(D7<0.01,"**",IF(D7<0.05,"*","n.s.")))) -> ** | F7: =IFERROR(CORREL(נתונים!$AT$3:$AT$302,נתונים!$AX$3:$AX$302),"") -> 0.33386609 | G7: =SUMPRODUCT(ISNUMBER(נתונים!$AT$3:$AT$302)*ISNUMBER(נתונים!$AX$3:$AX$302)) -> 71 | H7: =IFERROR(TDIST(ABS(F7)*SQRT((G7-2)/(1-F7^2)),G7-2,2),"") -> 0.0044354899 | I7: =IF(H7="","",IF(H7<0.001,"***",IF(H7<0.01,"**",IF(H7<0.05,"*","n.s.")))) -> ** | J7: =IFERROR(CORREL(נתונים!$AU$3:$AU$302,נתונים!$AY$3:$AY$302),"") -> 0.15288869 | K7: =SUMPRODUCT(ISNUMBER(נתונים!$AU$3:$AU$302)*ISNUMBER(נתונים!$AY$3:$AY$302)) -> 30 | L7: =IFERROR(TDIST(ABS(J7)*SQRT((K7-2)/(1-J7^2)),K7-2,2),"") -> 0.41990758 | M7: =IF(L7="","",IF(L7<0.001,"***",IF(L7<0.01,"**",IF(L7<0.05,"*","n.s.")))) -> n.s.
A8: קבלת החלטות × הנאה מלמידה | B8: =IFERROR(CORREL(נתונים!$AP$3:$AP$302,נתונים!$AQ$3:$AQ$302),"") -> 0.31055647 | C8: =SUMPRODUCT(ISNUMBER(נתונים!$AP$3:$AP$302)*ISNUMBER(נתונים!$AQ$3:$AQ$302)) -> 98 | D8: =IFERROR(TDIST(ABS(B8)*SQRT((C8-2)/(1-B8^2)),C8-2,2),"") -> 0.0018567305 | E8: =IF(D8="","",IF(D8<0.001,"***",IF(D8<0.01,"**",IF(D8<0.05,"*","n.s.")))) -> ** | F8: =IFERROR(CORREL(נתונים!$AV$3:$AV$302,נתונים!$AX$3:$AX$302),"") -> 0.36167267 | G8: =SUMPRODUCT(ISNUMBER(נתונים!$AV$3:$AV$302)*ISNUMBER(נתונים!$AX$3:$AX$302)) -> 70 | H8: =IFERROR(TDIST(ABS(F8)*SQRT((G8-2)/(1-F8^2)),G8-2,2),"") -> 0.00209553 | I8: =IF(H8="","",IF(H8<0.001,"***",IF(H8<0.01,"**",IF(H8<0.05,"*","n.s.")))) -> ** | J8: =IFERROR(CORREL(נתונים!$AW$3:$AW$302,נתונים!$AY$3:$AY$302),"") -> 0.073962059 | K8: =SUMPRODUCT(ISNUMBER(נתונים!$AW$3:$AW$302)*ISNUMBER(נתונים!$AY$3:$AY$302)) -> 28 | L8: =IFERROR(TDIST(ABS(J8)*SQRT((K8-2)/(1-J8^2)),K8-2,2),"") -> 0.70837457 | M8: =IF(L8="","",IF(L8<0.001,"***",IF(L8<0.01,"**",IF(L8<0.05,"*","n.s.")))) -> n.s.
A10: איך לקרוא: r חיובי = ככל שמשתנה אחד גבוה יותר, גם השני גבוה יותר. r≈.10 חלש, ≈.30 בינוני, ≥.50 חזק (Cohen, 1988).

Sheet השוואת קבוצות
A1: השוואה בין תלמידים טיפוסיים למתקשים (מבחן t של Welch)
A2: Welch אינו מניח שוויון שונויות. d של כהן: ≈.20 קטן, ≈.50 בינוני, ≥.80 גדול.
A4: משתנה | B4: N טיפוסי | C4: ממוצע טיפוסי | D4: ס"ת טיפוסי | E4: N מתקשה | F4: ממוצע מתקשה | G4: ס"ת מתקשה | H4: t | I4: df | J4: p | K4: מובהקות | L4: d של כהן
A5: יצירתיות | B5: =COUNT(נתונים!$AT$3:$AT$302) -> 72 | C5: =IFERROR(AVERAGE(נתונים!$AT$3:$AT$302),"") -> 3.609375 | D5: =IFERROR(STDEV(נתונים!$AT$3:$AT$302),"") -> 0.69515979 | E5: =COUNT(נתונים!$AU$3:$AU$302) -> 30 | F5: =IFERROR(AVERAGE(נתונים!$AU$3:$AU$302),"") -> 3.3166667 | G5: =IFERROR(STDEV(נתונים!$AU$3:$AU$302),"") -> 0.7931097 | H5: =IFERROR((C5-F5)/SQRT((D5^2/B5)+(G5^2/E5)),"") -> 1.7593746 | I5: =IFERROR(((D5^2/B5)+(G5^2/E5))^2/((D5^2/B5)^2/(B5-1)+(G5^2/E5)^2/(E5-1)),"") -> 48.507424 | J5: =IFERROR(TDIST(ABS(H5),I5,2),"") -> 0.084886595 | K5: =IF(J5="","",IF(J5<0.001,"***",IF(J5<0.01,"**",IF(J5<0.05,"*","n.s.")))) -> n.s. | L5: =IFERROR((C5-F5)/SQRT(((B5-1)*D5^2+(E5-1)*G5^2)/(B5+E5-2)),"") -> 0.40377514
A6: קבלת החלטות בפתרון בעיות | B6: =COUNT(נתונים!$AV$3:$AV$302) -> 71 | C6: =IFERROR(AVERAGE(נתונים!$AV$3:$AV$302),"") -> 3.2549296 | D6: =IFERROR(STDEV(נתונים!$AV$3:$AV$302),"") -> 0.74484682 | E6: =COUNT(נתונים!$AW$3:$AW$302) -> 28 | F6: =IFERROR(AVERAGE(נתונים!$AW$3:$AW$302),"") -> 3.0142857 | G6: =IFERROR(STDEV(נתונים!$AW$3:$AW$302),"") -> 0.83476068 | H6: =IFERROR((C6-F6)/SQRT((D6^2/B6)+(G6^2/E6)),"") -> 1.3307502 | I6: =IFERROR(((D6^2/B6)+(G6^2/E6))^2/((D6^2/B6)^2/(B6-1)+(G6^2/E6)^2/(E6-1)),"") -> 44.909327 | J6: =IFERROR(TDIST(ABS(H6),I6,2),"") -> 0.19012666 | K6: =IF(J6="","",IF(J6<0.001,"***",IF(J6<0.01,"**",IF(J6<0.05,"*","n.s.")))) -> n.s. | L6: =IFERROR((C6-F6)/SQRT(((B6-1)*D6^2+(E6-1)*G6^2)/(B6+E6-2)),"") -> 0.31214816
A7: הנאה מלמידה | B7: =COUNT(נתונים!$AX$3:$AX$302) -> 71 | C7: =IFERROR(AVERAGE(נתונים!$AX$3:$AX$302),"") -> 3.6390845 | D7: =IFERROR(STDEV(נתונים!$AX$3:$AX$302),"") -> 0.68123748 | E7: =COUNT(נתונים!$AY$3:$AY$302) -> 30 | F7: =IFERROR(AVERAGE(נתונים!$AY$3:$AY$302),"") -> 3.2166667 | G7: =IFERROR(STDEV(נתונים!$AY$3:$AY$302),"") -> 0.55216398 | H7: =IFERROR((C7-F7)/SQRT((D7^2/B7)+(G7^2/E7)),"") -> 3.2688421 | I7: =IFERROR(((D7^2/B7)+(G7^2/E7))^2/((D7^2/B7)^2/(B7-1)+(G7^2/E7)^2/(E7-1)),"") -> 66.844472 | J7: =IFERROR(TDIST(ABS(H7),I7,2),"") -> 0.0017170047 | K7: =IF(J7="","",IF(J7<0.001,"***",IF(J7<0.01,"**",IF(J7<0.05,"*","n.s.")))) -> ** | L7: =IFERROR((C7-F7)/SQRT(((B7-1)*D7^2+(E7-1)*G7^2)/(B7+E7-2)),"") -> 0.65379237
A9: t חיובי = הממוצע של התלמידים הטיפוסיים גבוה יותר. הערה: TDIST מעגל את df כלפי מטה למספר שלם, ולכן p עשוי להיות שמרני מעט.

Sheet מהימנות
A1: מהימנות פנימית – אלפא של קרונבך
A2: α ≥ .70 נחשב מקובל. מחושב על ההיגדים אחרי היפוך (החלטות 7–10).
A4: סולם | B4: מס' היגדים (k) | C4: סכום שונויות ההיגדים | D4: שונות הציון הכולל | E4: α קרונבך | F4: n שאלונים מלאים
A5: יצירתיות | B5: 8 | C5: =IFERROR(VAR(נתונים!$H$3:$H$302)+VAR(נתונים!$I$3:$I$302)+VAR(נתונים!$J$3:$J$302)+VAR(נתונים!$K$3:$K$302)+VAR(נתונים!$L$3:$L$302)+VAR(נתונים!$M$3:$M$302)+VAR(נתונים!$N$3:$N$302)+VAR(נתונים!$O$3:$O$302),"") -> 9.830033 | D5: =IFERROR(VAR(נתונים!$AL$3:$AL$302),"") -> 34.450107 | E5: =IFERROR(B5/(B5-1)*(1-C5/D5),"") -> 0.81675297 | F5: =COUNT(נתונים!$AL$3:$AL$302) -> 102
A6: קבלת החלטות בפתרון בעיות | B6: 10 | C6: =IFERROR(VAR(נתונים!$P$3:$P$302)+VAR(נתונים!$Q$3:$Q$302)+VAR(נתונים!$R$3:$R$302)+VAR(נתונים!$S$3:$S$302)+VAR(נתונים!$T$3:$T$302)+VAR(נתונים!$U$3:$U$302)+VAR(נתונים!$AH$3:$AH$302)+VAR(נתונים!$AI$3:$AI$302)+VAR(נתונים!$AJ$3:$AJ$302)+VAR(נתונים!$AK$3:$AK$302),"") -> 13.426942 | D6: =IFERROR(VAR(נתונים!$AM$3:$AM$302),"") -> 60.013193 | E6: =IFERROR(B6/(B6-1)*(1-C6/D6),"") -> 0.86251869 | F6: =COUNT(נתונים!$AM$3:$AM$302) -> 99
A7: הנאה מלמידה | B7: 8 | C7: =IFERROR(VAR(נתונים!$Z$3:$Z$302)+VAR(נתונים!$AA$3:$AA$302)+VAR(נתונים!$AB$3:$AB$302)+VAR(נתונים!$AC$3:$AC$302)+VAR(נתונים!$AD$3:$AD$302)+VAR(נתונים!$AE$3:$AE$302)+VAR(נתונים!$AF$3:$AF$302)+VAR(נתונים!$AG$3:$AG$302),"") -> 8.2535236 | D7: =IFERROR(VAR(נתונים!$AN$3:$AN$302),"") -> 28.85802 | E7: =IFERROR(B7/(B7-1)*(1-C7/D7),"") -> 0.81599485 | F7: =COUNT(נתונים!$AN$3:$AN$302) -> 101
A9: הערה: שונות כל היגד מחושבת על כל התשובות להיגד, ושונות הציון הכולל רק על שאלונים מלאים. כשכמעט כל השאלונים מלאים ההבדל זניח; לחישוב מדויק אפשר להשתמש ב-SPSS.

Sheet קידוד
A1: ספר קודים – איך מקלידים כל שאלה
A3: עמודה | B3: קוד | C3: שאלה / היגד | D3: ערכים להקלדה | E3: סולם | F3: היפוך? | G3: מקור
A4: A | B4: ID | C4: מספר שאלון (רץ: 1, 2, 3...) | D4: מספר שלם | E4: —
A5: B | B5: GENDER | C5: מגדר | D5: 1=בן, 2=בת | E5: —
A6: C | B6: GRADE | C6: כיתה | D6: 1=ז', 2=ח', 3=ט' | E6: —
A7: D | B7: AGE | C7: גיל | D7: מספר בשנים | E7: —
A8: E | B8: SCI | C8: הציון האחרון שלך במדעים בתעודה | D8: 1=מתחת ל-55, 2=55–69, 3=70–84, 4=85–100 | E8: —
A9: F | B9: DIAG | C9: האם אובחנת עם לקות למידה או הפרעת קשב? | D9: 1=כן, 2=לא, 3=לא יודע/ת | E9: —
A10: G | B10: SUPPORT | C10: האם את/ה מקבל/ת שעות תמיכה, שילוב או הוראה מתקנת? | D10: 1=כן, 2=לא | E10: —
A11: H | B11: C1 | C11: אני מצליח/ה לחשוב על פתרונות שרוב החברים שלי לא חושבים עליהם. | D11: 1–5 | E11: יצירתיות | G11: Park, Kang & Kim (2023), Frontiers in Psychology, 14, 1068554 – תרגום ועיבוד
A12: I | B12: C2 | C12: אני יכול/ה לחשוב על דברים שיעזרו לפתור בעיות חדשות. | D12: 1–5 | E12: יצירתיות | G12: Park, Kang & Kim (2023), Frontiers in Psychology, 14, 1068554 – תרגום ועיבוד
A13: J | B13: C3 | C13: גם כשאני שומע/ת רק חלק מהדברים, אני יכול/ה לדמיין את התמונה כולה. | D13: 1–5 | E13: יצירתיות | G13: Park, Kang & Kim (2023), Frontiers in Psychology, 14, 1068554 – תרגום ועיבוד
A14: K | B14: C4 | C14: אני מצליח/ה לחבר בין דברים שנראים לא קשורים זה לזה. | D14: 1–5 | E14: יצירתיות | G14: Park, Kang & Kim (2023), Frontiers in Psychology, 14, 1068554 – תרגום ועיבוד
A15: L | B15: C5 | C15: אני מצליח/ה למצוא הרבה רעיונות חדשים בזמן קצר. | D15: 1–5 | E15: יצירתיות | G15: Park, Kang & Kim (2023), Frontiers in Psychology, 14, 1068554 – תרגום ועיבוד
A16: M | B16: C6 | C16: אני טוב/ה בהעלאת רעיונות חדשים. | D16: 1–5 | E16: יצירתיות | G16: Beghetto (2006), Creativity Research Journal, 18, 447–457 – תרגום ועיבוד
A17: N | B17: C7 | C17: יש לי הרבה רעיונות טובים. | D17: 1–5 | E17: יצירתיות | G17: Beghetto (2006), Creativity Research Journal, 18, 447–457 – תרגום ועיבוד
A18: O | B18: C8 | C18: יש לי דמיון טוב. | D18: 1–5 | E18: יצירתיות | G18: Beghetto (2006), Creativity Research Journal, 18, 447–457 – תרגום ועיבוד
A19: P | B19: D1 | C19: אני אוהב/ת לשקול את כל האפשרויות לפני שאני מחליט/ה. | D19: 1–5 | E19: קבלת החלטות | G19: Mann et al. (1997), Melbourne Decision Making Questionnaire, J. of Behavioral Decision Making, 10, 1–19 – ערנות (vigilance), תרגום ועיבוד
A20: Q | B20: D2 | C20: אני מנסה לבדוק מה החסרונות של כל אפשרות. | D20: 1–5 | E20: קבלת החלטות | G20: Mann et al. (1997), Melbourne Decision Making Questionnaire, J. of Behavioral Decision Making, 10, 1–19 – ערנות (vigilance), תרגום ועיבוד
A21: R | B21: D3 | C21: אני חושב/ת מה הדרך הטובה ביותר לבצע את מה שהחלטתי. | D21: 1–5 | E21: קבלת החלטות | G21: Mann et al. (1997), Melbourne Decision Making Questionnaire, J. of Behavioral Decision Making, 10, 1–19 – ערנות (vigilance), תרגום ועיבוד
A22: S | B22: D4 | C22: לפני שאני מחליט/ה, אני אוסף/ת כמה שיותר מידע. | D22: 1–5 | E22: קבלת החלטות | G22: Mann et al. (1997), Melbourne Decision Making Questionnaire, J. of Behavioral Decision Making, 10, 1–19 – ערנות (vigilance), תרגום ועיבוד
... A24: U | B24: D6 | C24: אני בוחר/ת פתרון בזהירות ולא בחיפזון. | D24: 1–5 | E24: קבלת החלטות | G24: Mann et al. (1997), Melbourne Decision Making Questionnaire, J. of Behavioral Decision Making, 10, 1–19 – ערנות (vigilance), תרגום ועיבוד
